Workbook

Sheet Read Me
A1: Aggregate daily-cost formula — how this workbook works
A3: Goal: produce a Budget / Mid-range / Luxury daily-cost figure per city, built from data already on the
A4: Never Roam Alone site (the same numbers behind each city's cost cards), instead of a hand-typed guess.
A6: Formula (per person, per day):
A7: Total = Accommodation (per person) + Meals + Local transport + Baseline drinks
A8: + Alcohol (optional toggle) + Activities/tours (optional toggle)
A10: Where each piece comes from:
A11: Accommodation — the site's own 3-tier hotel prices (budget/mid/luxury nightly rate), divided by the
A12: 'people sharing a room' assumption (2 by default) to get a per-person figure — a
A13: solo traveler paying for a whole room alone should double this back up.
A14: Meals — site's 'inexpensive meal' price x meals/day x a tier multiplier (cheap meals for Budget,
A15: a mix of casual + nicer restaurants for Mid, mostly fine dining for Luxury).
... A41: city.html, plus the assumptions listed above — it doesn't call Numbeo or any live pricing source.

Sheet Assumptions
A1: Assumption | B1: Value | C1: Notes
A2: People sharing a hotel room | B2: 2 | C2: Accommodation is divided by this number to get a per-person nightly cost. Set to 1 if you want solo-traveler (whole room) pricing instead.
A3: Meals per day | B3: 3 | C3: Standard 3 meals/day for every tier.
A4: Meal cost multiplier — Budget | B4: 1 | C4: Budget traveler sticks to the site's 'inexpensive meal' price as-is.
A5: Meal cost multiplier — Mid | B5: 1.8 | C5: Mid-range traveler mixes casual spots with a nicer restaurant meal.
A6: Meal cost multiplier — Luxury | B6: 3.5 | C6: Luxury traveler eats mostly at higher-end restaurants.
A7: Taxi/rideshare trips per day — Budget | B7: 1 | C7: Budget traveler takes one short paid ride/day (walks or uses transit otherwise).
A8: Taxi/rideshare trips per day — Mid | B8: 2 | C8: Mid-range traveler takes two rides/day.
A9: Taxi/rideshare trips per day — Luxury | B9: 4 | C9: Luxury traveler relies on taxis/private transport more often.
A10: Alcoholic drinks per day — Budget | B10: 1 | C10: Only applied if 'Include alcoholic beverages?' below is TRUE.
A11: Alcoholic drinks per day — Mid | B11: 2 | C11: Only applied if 'Include alcoholic beverages?' below is TRUE.
A12: Alcoholic drinks per day — Luxury | B12: 3 | C12: Only applied if 'Include alcoholic beverages?' below is TRUE.
A13: Include alcoholic beverages? | B13: =TRUE() -> TRUE | C13: Global toggle — matches the 'Include alcoholic beverages' checkbox on the live Daily Cost Estimator card. Automatically skipped for cities where alcohol is restricted/not allowed regardless of this toggle.
A14: Include activities/tours? | B14: =TRUE() -> TRUE | C14: Global toggle — matches the 'Include activities/tours' checkbox on the live Daily Cost Estimator card.
A15: Activities as % of core cost — Budget | B15: 0.1 | C15: Core cost = accommodation + meals + transport + baseline drinks. No real per-city activities data exists yet, so this is a placeholder assumption.
A16: Activities as % of core cost — Mid | B16: 0.2 | C16: Placeholder assumption — adjust freely.
A17: Activities as % of core cost — Luxury | B17: 0.35 | C17: Placeholder assumption — adjust freely.
A18: Review-flag threshold (% diff from current site figure) | B18: 0.25 | C18: Any tier more than this % away from the live site number gets flagged REVIEW on the Computed tab.

Sheet City Data
A1: City | B1: Hotel Budget ($/night) | C1: Hotel Mid ($/night) | D1: Hotel Luxury ($/night) | E1: Meal Price ($, inexpensive meal) | F1: Taxi Price ($, short ride) | G1: Coffee Price ($) | H1: Water Price ($) | I1: Beer Price ($, blank = not sold) | J1: Alcohol Status (if not sold) | K1: Current Site Budget ($/day) | L1: Current Site Mid ($/day) | M1: Current Site High ($/day)
A2: Abidjan | B2: 35 | C2: 75 | D2: 220 | E2: 15 | F2: 7 | G2: 2.5 | H2: 0.8 | I2: 3 | K2: 50 | L2: 120 | M2: 355
A3: Abu Dhabi | B3: 75 | C3: 140 | D3: 400 | E3: 30 | F3: 15 | G3: 5 | H3: 1 | J3: restricted | K3: 70 | L3: 185 | M3: 600
A4: Accra | B4: 30 | C4: 90 | D4: 280 | E4: 12 | F4: 5 | G4: 3 | H4: 0.8 | I4: 2.5 | K4: 45 | L4: 115 | M4: 350
A5: Addis Ababa | B5: 15 | C5: 70 | D5: 280 | E5: 8 | F5: 4 | G5: 1.05 | H5: 0.49 | I5: 0.95 | K5: 35 | L5: 90 | M5: 295
A6: Ahmedabad | B6: 15 | C6: 40 | D6: 110 | E6: 4 | F6: 3 | G6: 1.5 | H6: 0.3 | I6: 6 | K6: 25 | L6: 60 | M6: 180
A7: Alexandria | B7: 20 | C7: 70 | D7: 180 | E7: 6 | F7: 3 | G7: 1.5 | H7: 0.4 | I7: 3 | K7: 30 | L7: 75 | M7: 250
A8: Algiers | B8: 35 | C8: 65 | D8: 180 | E8: 9 | F8: 5 | G8: 1.3 | H8: 0.5 | I8: 4 | K8: 40 | L8: 100 | M8: 285
A9: Almaty | B9: 25 | C9: 72 | D9: 220 | E9: 15 | F9: 4 | G9: 2.4 | H9: 0.5 | I9: 2 | K9: 45 | L9: 110 | M9: 335
A10: Amman | B10: 40 | C10: 90 | D10: 220 | E10: 18 | F10: 5 | G10: 3 | H10: 1 | I10: 7 | K10: 50 | L10: 130 | M10: 385
A11: Amsterdam | B11: 80 | C11: 160 | D11: 380 | E11: 28 | F11: 25 | G11: 3.5 | H11: 1.5 | I11: 6 | K11: 90 | L11: 220 | M11: 600
A12: Andorra la Vella | B12: 55 | C12: 115 | D12: 240 | E12: 24 | F12: 10 | G12: 2.2 | H12: 1.3 | I12: 4.5 | K12: 65 | L12: 160 | M12: 465
A13: Ankara | B13: 20 | C13: 55 | D13: 130 | E13: 9 | F13: 5 | G13: 2.2 | H13: 0.4 | I13: 3 | K13: 30 | L13: 75 | M13: 220
A14: Antalya | B14: 25 | C14: 55 | D14: 160 | E14: 12 | F14: 7 | G14: 3 | H14: 0.4 | I14: 4 | K14: 40 | L14: 95 | M14: 280
A15: Antananarivo | B15: 20 | C15: 55 | D15: 150 | E15: 8 | F15: 4 | G15: 1.5 | H15: 0.5 | I15: 2 | K15: 35 | L15: 80 | M15: 245
... A24: Bamako | B24: 28 | C24: 90 | D24: 180 | E24: 12 | F24: 4 | G24: 2 | H24: 0.7 | I24: 3 | K24: 40 | L24: 100 | M24: 300
A25: Bandar Seri Begawan | B25: 25 | C25: 75 | D25: 150 | E25: 12 | F25: 10 | G25: 3 | H25: 1 | J25: restricted | K25: 40 | L25: 100 | M25: 285
A26: Bangkok | B26: 18 | C26: 45 | D26: 150 | E26: 8 | F26: 5 | G26: 2.5 | H26: 0.5 | I26: 3 | K26: 35 | L26: 90 | M26: 250
A27: Bangui | B27: 30 | C27: 70 | D27: 200 | E27: 12 | F27: 4 | G27: 2.5 | H27: 1 | I27: 2 | K27: 40 | L27: 105 | M27: 310
A28: Banjul | B28: 25 | C28: 55 | D28: 150 | E28: 8 | F28: 6 | G28: 2.5 | H28: 0.6 | I28: 3 | K28: 35 | L28: 85 | M28: 250
A29: Barcelona | B29: 55 | C29: 120 | D29: 300 | E29: 22 | F29: 15 | G29: 2 | H29: 1 | I29: 3.5 | K29: 75 | L29: 180 | M29: 500
A30: Basseterre | B30: 80 | C30: 150 | D30: 550 | E30: 25 | F30: 18 | G30: 3 | H30: 1.5 | I30: 5 | K30: 85 | L30: 220 | M30: 650
A31: Beijing | B31: 35 | C31: 80 | D31: 250 | E31: 12 | F31: 8 | G31: 4.5 | H31: 0.5 | I31: 3 | K31: 55 | L31: 135 | M31: 380
A32: Beirut | B32: 40 | C32: 90 | D32: 260 | E32: 18 | F32: 8 | G32: 3.5 | H32: 1 | I32: 6 | K32: 55 | L32: 135 | M32: 400
A33: Belgrade | B33: 25 | C33: 75 | D33: 220 | E33: 15 | F33: 6 | G33: 3 | H33: 1 | I33: 3 | K33: 45 | L33: 110 | M33: 340
A34: Belize City | B34: 35 | C34: 90 | D34: 220 | E34: 12 | F34: 7 | G34: 2.5 | H34: 1.5 | I34: 3 | K34: 45 | L34: 110 | M34: 330
A35: Bengaluru | B35: 20 | C35: 55 | D35: 130 | E35: 6 | F35: 3 | G35: 1.5 | H35: 0.4 | I35: 3 | K35: 30 | L35: 75 | M35: 220
A36: Berlin | B36: 60 | C36: 110 | D36: 260 | E36: 18 | F36: 25 | G36: 3.2 | H36: 2.5 | I36: 4 | K36: 70 | L36: 170 | M36: 470
A37: Bishkek | B37: 15 | C37: 45 | D37: 180 | E37: 8 | F37: 3 | G37: 2 | H37: 0.4 | I37: 1.3 | K37: 30 | L37: 80 | M37: 250
... A69: Denpasar | B69: 25 | C69: 60 | D69: 180 | E69: 12 | F69: 12 | G69: 2 | H69: 0.5 | I69: 2.5 | K69: 35 | L69: 85 | M69: 280
A70: Dhaka | B70: 20 | C70: 70 | D70: 180 | E70: 6 | F70: 4 | G70: 2.5 | H70: 0.3 | J70: restricted | K70: 30 | L70: 80 | M70: 240
A71: Dili | B71: 20 | C71: 70 | D71: 150 | E71: 10 | F71: 4 | G71: 2 | H71: 1 | I71: 3.5 | K71: 35 | L71: 85 | M71: 260
A72: Djibouti City | B72: 30 | C72: 90 | D72: 260 | E72: 12 | F72: 5 | G72: 2.5 | H72: 1 | I72: 5 | K72: 45 | L72: 110 | M72: 340
A73: Doha | B73: 80 | C73: 150 | D73: 400 | E73: 30 | F73: 15 | G73: 5 | H73: 1 | J73: restricted | K73: 70 | L73: 180 | M73: 550
A74: Dongguan | B74: 20 | C74: 55 | D74: 130 | E74: 6 | F74: 4 | G74: 3.5 | H74: 0.4 | I74: 1.5 | K74: 30 | L74: 75 | M74: 200
A75: Douala | B75: 30 | C75: 75 | D75: 250 | E75: 10 | F75: 5 | G75: 2.5 | H75: 0.6 | I75: 2 | K75: 40 | L75: 105 | M75: 320
A76: Dubai | B76: 50 | C76: 120 | D76: 350 | E76: 25 | F76: 8 | G76: 4.5 | H76: 0.5 | J76: restricted | K76: 75 | L76: 200 | M76: 650
A77: Dublin | B77: 90 | C77: 160 | D77: 350 | E77: 25 | F77: 30 | G77: 3.5 | H77: 2 | I77: 6.5 | K77: 85 | L77: 210 | M77: 580
A78: Dubrovnik | B78: 50 | C78: 160 | D78: 420 | E78: 25 | F78: 15 | G78: 3 | H78: 2 | I78: 4.5 | K78: 70 | L78: 180 | M78: 545
A79: Dushanbe | B79: 15 | C79: 55 | D79: 180 | E79: 10 | F79: 3 | G79: 2 | H79: 0.5 | I79: 1.5 | K79: 35 | L79: 85 | M79: 265
...

Sheet Computed
A1: City | B1: Accommodation — Budget | C1: Accommodation — Mid | D1: Accommodation — Luxury | E1: Meals — Budget | F1: Meals — Mid | G1: Meals — Luxury | H1: Local transport — Budget | I1: Local transport — Mid | J1: Local transport — Luxury | K1: Baseline drinks (coffee+water) | L1: Alcohol — Budget | M1: Alcohol — Mid | N1: Alcohol — Luxury | O1: Core subtotal — Budget | P1: Core subtotal — Mid | Q1: Core subtotal — Luxury | R1: Activities/tours — Budget | S1: Activities/tours — Mid | T1: Activities/tours — Luxury | U1: NEW Total — Budget | V1: NEW Total — Mid | W1: NEW Total — Luxury | X1: Current Site — Budget | Y1: Current Site — Mid | Z1: Current Site — Luxury | AA1: Diff — Budget | AB1: Diff — Mid | AC1: Diff — Luxury | AD1: Flag
A2: ='City Data'!A2 -> Abidjan | B2: ='City Data'!B2/Assumptions!$B$2 -> 17.5 | C2: ='City Data'!C2/Assumptions!$B$2 -> 37.5 | D2: ='City Data'!D2/Assumptions!$B$2 -> 110 | E2: =Assumptions!$B$3*Assumptions!$B$4*'City Data'!E2 -> 45 | F2: =Assumptions!$B$3*Assumptions!$B$5*'City Data'!E2 -> 81 | G2: =Assumptions!$B$3*Assumptions!$B$6*'City Data'!E2 -> 157.5 | H2: =Assumptions!$B$7*'City Data'!F2 -> 7 | I2: =Assumptions!$B$8*'City Data'!F2 -> 14 | J2: =Assumptions!$B$9*'City Data'!F2 -> 28 | K2: ='City Data'!G2+'City Data'!H2 -> 3.3 | L2: =IF(AND(Assumptions!$B$13,ISNUMBER('City Data'!I2)),Assumptions!$B$10*'City Data'!I2,0) -> 3 | M2: =IF(AND(Assumptions!$B$13,ISNUMBER('City Data'!I2)),Assumptions!$B$11*'City Data'!I2,0) -> 6 | N2: =IF(AND(Assumptions!$B$13,ISNUMBER('City Data'!I2)),Assumptions!$B$12*'City Data'!I2,0) -> 9 | O2: =B2+E2+H2+K2 -> 72.8 | P2: =C2+F2+I2+K2 -> 135.8 | Q2: =D2+G2+J2+K2 -> 298.8 | R2: =IF(Assumptions!$B$14,Assumptions!$B$15*O2,0) -> 7.28 | S2: =IF(Assumptions!$B$14,Assumptions!$B$16*P2,0) -> 27.16 | T2: =IF(Assumptions!$B$14,Assumptions!$B$17*Q2,0) -> 104.58 | U2: =O2+L2+R2 -> 83.08 | V2: =P2+M2+S2 -> 168.96 | W2: =Q2+N2+T2 -> 412.38 | X2: ='City Data'!K2 -> 50 | Y2: ='City Data'!L2 -> 120 | Z2: ='City Data'!M2 -> 355 | AA2: =U2-X2 -> 33.08 | AB2: =V2-Y2 -> 48.96 | AC2: =W2-Z2 -> 57.38 | AD2: =IF(OR(AND(X2<>0,ABS(AA2)>Assumptions!$B$18*X2),AND(Y2<>0,ABS(AB2)>Assumptions!$B$18*Y2),AND(Z2<>0,ABS(AC2)>Assumptions!$B$18*Z2)),"REVIEW","") -> REVIEW
A3: ='City Data'!A3 -> Abu Dhabi | B3: ='City Data'!B3/Assumptions!$B$2 -> 37.5 | C3: ='City Data'!C3/Assumptions!$B$2 -> 70 | D3: ='City Data'!D3/Assumptions!$B$2 -> 200 | E3: =Assumptions!$B$3*Assumptions!$B$4*'City Data'!E3 -> 90 | F3: =Assumptions!$B$3*Assumptions!$B$5*'City Data'!E3 -> 162 | G3: =Assumptions!$B$3*Assumptions!$B$6*'City Data'!E3 -> 315 | H3: =Assumptions!$B$7*'City Data'!F3 -> 15 | I3: =Assumptions!$B$8*'City Data'!F3 -> 30 | J3: =Assumptions!$B$9*'City Data'!F3 -> 60 | K3: ='City Data'!G3+'City Data'!H3 -> 6 | L3: =IF(AND(Assumptions!$B$13,ISNUMBER('City Data'!I3)),Assumptions!$B$10*'City Data'!I3,0) -> 0 | M3: =IF(AND(Assumptions!$B$13,ISNUMBER('City Data'!I3)),Assumptions!$B$11*'City Data'!I3,0) -> 0 | N3: =IF(AND(Assumptions!$B$13,ISNUMBER('City Data'!I3)),Assumptions!$B$12*'City Data'!I3,0) -> 0 | O3: =B3+E3+H3+K3 -> 148.5 | P3: =C3+F3+I3+K3 -> 268 | Q3: =D3+G3+J3+K3 -> 581 | R3: =IF(Assumptions!$B$14,Assumptions!$B$15*O3,0) -> 14.85 | S3: =IF(Assumptions!$B$14,Assumptions!$B$16*P3,0) -> 53.6 | T3: =IF(Assumptions!$B$14,Assumptions!$B$17*Q3,0) -> 203.35 | U3: =O3+L3+R3 -> 163.35 | V3: =P3+M3+S3 -> 321.6 | W3: =Q3+N3+T3 -> 784.35 | X3: ='City Data'!K3 -> 70 | Y3: ='City Data'!L3 -> 185 | Z3: ='City Data'!M3 -> 600 | AA3: =U3-X3 -> 93.35 | AB3: =V3-Y3 -> 136.6 | AC3: =W3-Z3 -> 184.35 | AD3: =IF(OR(AND(X3<>0,ABS(AA3)>Assumptions!$B$18*X3),AND(Y3<>0,ABS(AB3)>Assumptions!$B$18*Y3),AND(Z3<>0,ABS(AC3)>Assumptions!$B$18*Z3)),"REVIEW","") -> REVIEW
A4: ='City Data'!A4 -> Accra | B4: ='City Data'!B4/Assumptions!$B$2 -> 15 | C4: ='City Data'!C4/Assumptions!$B$2 -> 45 | D4: ='City Data'!D4/Assumptions!$B$2 -> 140 | E4: =Assumptions!$B$3*Assumptions!$B$4*'City Data'!E4 -> 36 | F4: =Assumptions!$B$3*Assumptions!$B$5*'City Data'!E4 -> 64.8 | G4: =Assumptions!$B$3*Assumptions!$B$6*'City Data'!E4 -> 126 | H4: =Assumptions!$B$7*'City Data'!F4 -> 5 | I4: =Assumptions!$B$8*'City Data'!F4 -> 10 | J4: =Assumptions!$B$9*'City Data'!F4 -> 20 | K4: ='City Data'!G4+'City Data'!H4 -> 3.8 | L4: =IF(AND(Assumptions!$B$13,ISNUMBER('City Data'!I4)),Assumptions!$B$10*'City Data'!I4,0) -> 2.5 | M4: =IF(AND(Assumptions!$B$13,ISNUMBER('City Data'!I4)),Assumptions!$B$11*'City Data'!I4,0) -> 5 | N4: =IF(AND(Assumptions!$B$13,ISNUMBER('City Data'!I4)),Assumptions!$B$12*'City Data'!I4,0) -> 7.5 | O4: =B4+E4+H4+K4 -> 59.8 | P4: =C4+F4+I4+K4 -> 123.6 | Q4: =D4+G4+J4+K4 -> 289.8 | R4: =IF(Assumptions!$B$14,Assumptions!$B$15*O4,0) -> 5.98 | S4: =IF(Assumptions!$B$14,Assumptions!$B$16*P4,0) -> 24.72 | T4: =IF(Assumptions!$B$14,Assumptions!$B$17*Q4,0) -> 101.43 | U4: =O4+L4+R4 -> 68.28 | V4: =P4+M4+S4 -> 153.32 | W4: =Q4+N4+T4 -> 398.73 | X4: ='City Data'!K4 -> 45 | Y4: ='City Data'!L4 -> 115 | Z4: ='City Data'!M4 -> 350 | AA4: =U4-X4 -> 23.28 | AB4: =V4-Y4 -> 38.32 | AC4: =W4-Z4 -> 48.73 | AD4: =IF(OR(AND(X4<>0,ABS(AA4)>Assumptions!$B$18*X4),AND(Y4<>0,ABS(AB4)>Assumptions!$B$18*Y4),AND(Z4<>0,ABS(AC4)>Assumptions!$B$18*Z4)),"REVIEW","") -> REVIEW
A5: ='City Data'!A5 -> Addis Ababa | B5: ='City Data'!B5/Assumptions!$B$2 -> 7.5 | C5: ='City Data'!C5/Assumptions!$B$2 -> 35 | D5: ='City Data'!D5/Assumptions!$B$2 -> 140 | E5: =Assumptions!$B$3*Assumptions!$B$4*'City Data'!E5 -> 24 | F5: =Assumptions!$B$3*Assumptions!$B$5*'City Data'!E5 -> 43.2 | G5: =Assumptions!$B$3*Assumptions!$B$6*'City Data'!E5 -> 84 | H5: =Assumptions!$B$7*'City Data'!F5 -> 4 | I5: =Assumptions!$B$8*'City Data'!F5 -> 8 | J5: =Assumptions!$B$9*'City Data'!F5 -> 16 | K5: ='City Data'!G5+'City Data'!H5 -> 1.54 | L5: =IF(AND(Assumptions!$B$13,ISNUMBER('City Data'!I5)),Assumptions!$B$10*'City Data'!I5,0) -> 0.95 | M5: =IF(AND(Assumptions!$B$13,ISNUMBER('City Data'!I5)),Assumptions!$B$11*'City Data'!I5,0) -> 1.9 | N5: =IF(AND(Assumptions!$B$13,ISNUMBER('City Data'!I5)),Assumptions!$B$12*'City Data'!I5,0) -> 2.85 | O5: =B5+E5+H5+K5 -> 37.04 | P5: =C5+F5+I5+K5 -> 87.74 | Q5: =D5+G5+J5+K5 -> 241.54 | R5: =IF(Assumptions!$B$14,Assumptions!$B$15*O5,0) -> 3.704 | S5: =IF(Assumptions!$B$14,Assumptions!$B$16*P5,0) -> 17.548 | T5: =IF(Assumptions!$B$14,Assumptions!$B$17*Q5,0) -> 84.539 | U5: =O5+L5+R5 -> 41.694 | V5: =P5+M5+S5 -> 107.188 | W5: =Q5+N5+T5 -> 328.929 | X5: ='City Data'!K5 -> 35 | Y5: ='City Data'!L5 -> 90 | Z5: ='City Data'!M5 -> 295 | AA5: =U5-X5 -> 6.694 | AB5: =V5-Y5 -> 17.188 | AC5: =W5-Z5 -> 33.929 | AD5: =IF(OR(AND(X5<>0,ABS(AA5)>Assumptions!$B$18*X5),AND(Y5<>0,ABS(AB5)>Assumptions!$B$18*Y5),AND(Z5<>0,ABS(AC5)>Assumptions!$B$18*Z5)),"REVIEW","")
A6: ='City Data'!A6 -> Ahmedabad | B6: ='City Data'!B6/Assumptions!$B$2 -> 7.5 | C6: ='City Data'!C6/Assumptions!$B$2 -> 20 | D6: ='City Data'!D6/Assumptions!$B$2 -> 55 | E6: =Assumptions!$B$3*Assumptions!$B$4*'City Data'!E6 -> 12 | F6: =Assumptions!$B$3*Assumptions!$B$5*'City Data'!E6 -> 21.6 | G6: =Assumptions!$B$3*Assumptions!$B$6*'City Data'!E6 -> 42 | H6: =Assumptions!$B$7*'City Data'!F6 -> 3 | I6: =Assumptions!$B$8*'City Data'!F6 -> 6 | J6: =Assumptions!$B$9*'City Data'!F6 -> 12 | K6: ='City Data'!G6+'City Data'!H6 -> 1.8 | L6: =IF(AND(Assumptions!$B$13,ISNUMBER('City Data'!I6)),Assumptions!$B$10*'City Data'!I6,0) -> 6 | M6: =IF(AND(Assumptions!$B$13,ISNUMBER('City Data'!I6)),Assumptions!$B$11*'City Data'!I6,0) -> 12 | N6: =IF(AND(Assumptions!$B$13,ISNUMBER('City Data'!I6)),Assumptions!$B$12*'City Data'!I6,0) -> 18 | O6: =B6+E6+H6+K6 -> 24.3 | P6: =C6+F6+I6+K6 -> 49.4 | Q6: =D6+G6+J6+K6 -> 110.8 | R6: =IF(Assumptions!$B$14,Assumptions!$B$15*O6,0) -> 2.43 | S6: =IF(Assumptions!$B$14,Assumptions!$B$16*P6,0) -> 9.88 | T6: =IF(Assumptions!$B$14,Assumptions!$B$17*Q6,0) -> 38.78 | U6: =O6+L6+R6 -> 32.73 | V6: =P6+M6+S6 -> 71.28 | W6: =Q6+N6+T6 -> 167.58 | X6: ='City Data'!K6 -> 25 | Y6: ='City Data'!L6 -> 60 | Z6: ='City Data'!M6 -> 180 | AA6: =U6-X6 -> 7.73 | AB6: =V6-Y6 -> 11.28 | AC6: =W6-Z6 -> -12.42 | AD6: =IF(OR(AND(X6<>0,ABS(AA6)>Assumptions!$B$18*X6),AND(Y6<>0,ABS(AB6)>Assumptions!$B$18*Y6),AND(Z6<>0,ABS(AC6)>Assumptions!$B$18*Z6)),"REVIEW","") -> REVIEW
A7: ='City Data'!A7 -> Alexandria | B7: ='City Data'!B7/Assumptions!$B$2 -> 10 | C7: ='City Data'!C7/Assumptions!$B$2 -> 35 | D7: ='City Data'!D7/Assumptions!$B$2 -> 90 | E7: =Assumptions!$B$3*Assumptions!$B$4*'City Data'!E7 -> 18 | F7: =Assumptions!$B$3*Assumptions!$B$5*'City Data'!E7 -> 32.4 | G7: =Assumptions!$B$3*Assumptions!$B$6*'City Data'!E7 -> 63 | H7: =Assumptions!$B$7*'City Data'!F7 -> 3 | I7: =Assumptions!$B$8*'City Data'!F7 -> 6 | J7: =Assumptions!$B$9*'City Data'!F7 -> 12 | K7: ='City Data'!G7+'City Data'!H7 -> 1.9 | L7: =IF(AND(Assumptions!$B$13,ISNUMBER('City Data'!I7)),Assumptions!$B$10*'City Data'!I7,0) -> 3 | M7: =IF(AND(Assumptions!$B$13,ISNUMBER('City Data'!I7)),Assumptions!$B$11*'City Data'!I7,0) -> 6 | N7: =IF(AND(Assumptions!$B$13,ISNUMBER('City Data'!I7)),Assumptions!$B$12*'City Data'!I7,0) -> 9 | O7: =B7+E7+H7+K7 -> 32.9 | P7: =C7+F7+I7+K7 -> 75.3 | Q7: =D7+G7+J7+K7 -> 166.9 | R7: =IF(Assumptions!$B$14,Assumptions!$B$15*O7,0) -> 3.29 | S7: =IF(Assumptions!$B$14,Assumptions!$B$16*P7,0) -> 15.06 | T7: =IF(Assumptions!$B$14,Assumptions!$B$17*Q7,0) -> 58.415 | U7: =O7+L7+R7 -> 39.19 | V7: =P7+M7+S7 -> 96.36 | W7: =Q7+N7+T7 -> 234.315 | X7: ='City Data'!K7 -> 30 | Y7: ='City Data'!L7 -> 75 | Z7: ='City Data'!M7 -> 250 | AA7: =U7-X7 -> 9.19 | AB7: =V7-Y7 -> 21.36 | AC7: =W7-Z7 -> -15.685 | AD7: =IF(OR(AND(X7<>0,ABS(AA7)>Assumptions!$B$18*X7),AND(Y7<>0,ABS(AB7)>Assumptions!$B$18*Y7),AND(Z7<>0,ABS(AC7)>Assumptions!$B$18*Z7)),"REVIEW","") -> REVIEW
A8: ='City Data'!A8 -> Algiers | B8: ='City Data'!B8/Assumptions!$B$2 -> 17.5 | C8: ='City Data'!C8/Assumptions!$B$2 -> 32.5 | D8: ='City Data'!D8/Assumptions!$B$2 -> 90 | E8: =Assumptions!$B$3*Assumptions!$B$4*'City Data'!E8 -> 27 | F8: =Assumptions!$B$3*Assumptions!$B$5*'City Data'!E8 -> 48.6 | G8: =Assumptions!$B$3*Assumptions!$B$6*'City Data'!E8 -> 94.5 | H8: =Assumptions!$B$7*'City Data'!F8 -> 5 | I8: =Assumptions!$B$8*'City Data'!F8 -> 10 | J8: =Assumptions!$B$9*'City Data'!F8 -> 20 | K8: ='City Data'!G8+'City Data'!H8 -> 1.8 | L8: =IF(AND(Assumptions!$B$13,ISNUMBER('City Data'!I8)),Assumptions!$B$10*'City Data'!I8,0) -> 4 | M8: =IF(AND(Assumptions!$B$13,ISNUMBER('City Data'!I8)),Assumptions!$B$11*'City Data'!I8,0) -> 8 | N8: =IF(AND(Assumptions!$B$13,ISNUMBER('City Data'!I8)),Assumptions!$B$12*'City Data'!I8,0) -> 12 | O8: =B8+E8+H8+K8 -> 51.3 | P8: =C8+F8+I8+K8 -> 92.9 | Q8: =D8+G8+J8+K8 -> 206.3 | R8: =IF(Assumptions!$B$14,Assumptions!$B$15*O8,0) -> 5.13 | S8: =IF(Assumptions!$B$14,Assumptions!$B$16*P8,0) -> 18.58 | T8: =IF(Assumptions!$B$14,Assumptions!$B$17*Q8,0) -> 72.205 | U8: =O8+L8+R8 -> 60.43 | V8: =P8+M8+S8 -> 119.48 | W8: =Q8+N8+T8 -> 290.505 | X8: ='City Data'!K8 -> 40 | Y8: ='City Data'!L8 -> 100 | Z8: ='City Data'!M8 -> 285 | AA8: =U8-X8 -> 20.43 | AB8: =V8-Y8 -> 19.48 | AC8: =W8-Z8 -> 5.505 | AD8: =IF(OR(AND(X8<>0,ABS(AA8)>Assumptions!$B$18*X8),AND(Y8<>0,ABS(AB8)>Assumptions!$B$18*Y8),AND(Z8<>0,ABS(AC8)>Assumptions!$B$18*Z8)),"REVIEW","") -> REVIEW
A9: ='City Data'!A9 -> Almaty | B9: ='City Data'!B9/Assumptions!$B$2 -> 12.5 | C9: ='City Data'!C9/Assumptions!$B$2 -> 36 | D9: ='City Data'!D9/Assumptions!$B$2 -> 110 | E9: =Assumptions!$B$3*Assumptions!$B$4*'City Data'!E9 -> 45 | F9: =Assumptions!$B$3*Assumptions!$B$5*'City Data'!E9 -> 81 | G9: =Assumptions!$B$3*Assumptions!$B$6*'City Data'!E9 -> 157.5 | H9: =Assumptions!$B$7*'City Data'!F9 -> 4 | I9: =Assumptions!$B$8*'City Data'!F9 -> 8 | J9: =Assumptions!$B$9*'City Data'!F9 -> 16 | K9: ='City Data'!G9+'City Data'!H9 -> 2.9 | L9: =IF(AND(Assumptions!$B$13,ISNUMBER('City Data'!I9)),Assumptions!$B$10*'City Data'!I9,0) -> 2 | M9: =IF(AND(Assumptions!$B$13,ISNUMBER('City Data'!I9)),Assumptions!$B$11*'City Data'!I9,0) -> 4 | N9: =IF(AND(Assumptions!$B$13,ISNUMBER('City Data'!I9)),Assumptions!$B$12*'City Data'!I9,0) -> 6 | O9: =B9+E9+H9+K9 -> 64.4 | P9: =C9+F9+I9+K9 -> 127.9 | Q9: =D9+G9+J9+K9 -> 286.4 | R9: =IF(Assumptions!$B$14,Assumptions!$B$15*O9,0) -> 6.44 | S9: =IF(Assumptions!$B$14,Assumptions!$B$16*P9,0) -> 25.58 | T9: =IF(Assumptions!$B$14,Assumptions!$B$17*Q9,0) -> 100.24 | U9: =O9+L9+R9 -> 72.84 | V9: =P9+M9+S9 -> 157.48 | W9: =Q9+N9+T9 -> 392.64 | X9: ='City Data'!K9 -> 45 | Y9: ='City Data'!L9 -> 110 | Z9: ='City Data'!M9 -> 335 | AA9: =U9-X9 -> 27.84 | AB9: =V9-Y9 -> 47.48 | AC9: =W9-Z9 -> 57.64 | AD9: =IF(OR(AND(X9<>0,ABS(AA9)>Assumptions!$B$18*X9),AND(Y9<>0,ABS(AB9)>Assumptions!$B$18*Y9),AND(Z9<>0,ABS(AC9)>Assumptions!$B$18*Z9)),"REVIEW","") -> REVIEW
A10: ='City Data'!A10 -> Amman | B10: ='City Data'!B10/Assumptions!$B$2 -> 20 | C10: ='City Data'!C10/Assumptions!$B$2 -> 45 | D10: ='City Data'!D10/Assumptions!$B$2 -> 110 | E10: =Assumptions!$B$3*Assumptions!$B$4*'City Data'!E10 -> 54 | F10: =Assumptions!$B$3*Assumptions!$B$5*'City Data'!E10 -> 97.2 | G10: =Assumptions!$B$3*Assumptions!$B$6*'City Data'!E10 -> 189 | H10: =Assumptions!$B$7*'City Data'!F10 -> 5 | I10: =Assumptions!$B$8*'City Data'!F10 -> 10 | J10: =Assumptions!$B$9*'City Data'!F10 -> 20 | K10: ='City Data'!G10+'City Data'!H10 -> 4 | L10: =IF(AND(Assumptions!$B$13,ISNUMBER('City Data'!I10)),Assumptions!$B$10*'City Data'!I10,0) -> 7 | M10: =IF(AND(Assumptions!$B$13,ISNUMBER('City Data'!I10)),Assumptions!$B$11*'City Data'!I10,0) -> 14 | N10: =IF(AND(Assumptions!$B$13,ISNUMBER('City Data'!I10)),Assumptions!$B$12*'City Data'!I10,0) -> 21 | O10: =B10+E10+H10+K10 -> 83 | P10: =C10+F10+I10+K10 -> 156.2 | Q10: =D10+G10+J10+K10 -> 323 | R10: =IF(Assumptions!$B$14,Assumptions!$B$15*O10,0) -> 8.3 | S10: =IF(Assumptions!$B$14,Assumptions!$B$16*P10,0) -> 31.24 | T10: =IF(Assumptions!$B$14,Assumptions!$B$17*Q10,0) -> 113.05 | U10: =O10+L10+R10 -> 98.3 | V10: =P10+M10+S10 -> 201.44 | W10: =Q10+N10+T10 -> 457.05 | X10: ='City Data'!K10 -> 50 | Y10: ='City Data'!L10 -> 130 | Z10: ='City Data'!M10 -> 385 | AA10: =U10-X10 -> 48.3 | AB10: =V10-Y10 -> 71.44 | AC10: =W10-Z10 -> 72.05 | AD10: =IF(OR(AND(X10<>0,ABS(AA10)>Assumptions!$B$18*X10),AND(Y10<>0,ABS(AB10)>Assumptions!$B$18*Y10),AND(Z10<>0,ABS(AC10)>Assumptions!$B$18*Z10)),"REVIEW","") -> REVIEW
A11: ='City Data'!A11 -> Amsterdam | B11: ='City Data'!B11/Assumptions!$B$2 -> 40 | C11: ='City Data'!C11/Assumptions!$B$2 -> 80 | D11: ='City Data'!D11/Assumptions!$B$2 -> 190 | E11: =Assumptions!$B$3*Assumptions!$B$4*'City Data'!E11 -> 84 | F11: =Assumptions!$B$3*Assumptions!$B$5*'City Data'!E11 -> 151.2 | G11: =Assumptions!$B$3*Assumptions!$B$6*'City Data'!E11 -> 294 | H11: =Assumptions!$B$7*'City Data'!F11 -> 25 | I11: =Assumptions!$B$8*'City Data'!F11 -> 50 | J11: =Assumptions!$B$9*'City Data'!F11 -> 100 | K11: ='City Data'!G11+'City Data'!H11 -> 5 | L11: =IF(AND(Assumptions!$B$13,ISNUMBER('City Data'!I11)),Assumptions!$B$10*'City Data'!I11,0) -> 6 | M11: =IF(AND(Assumptions!$B$13,ISNUMBER('City Data'!I11)),Assumptions!$B$11*'City Data'!I11,0) -> 12 | N11: =IF(AND(Assumptions!$B$13,ISNUMBER('City Data'!I11)),Assumptions!$B$12*'City Data'!I11,0) -> 18 | O11: =B11+E11+H11+K11 -> 154 | P11: =C11+F11+I11+K11 -> 286.2 | Q11: =D11+G11+J11+K11 -> 589 | R11: =IF(Assumptions!$B$14,Assumptions!$B$15*O11,0) -> 15.4 | S11: =IF(Assumptions!$B$14,Assumptions!$B$16*P11,0) -> 57.24 | T11: =IF(Assumptions!$B$14,Assumptions!$B$17*Q11,0) -> 206.15 | U11: =O11+L11+R11 -> 175.4 | V11: =P11+M11+S11 -> 355.44 | W11: =Q11+N11+T11 -> 813.15 | X11: ='City Data'!K11 -> 90 | Y11: ='City Data'!L11 -> 220 | Z11: ='City Data'!M11 -> 600 | AA11: =U11-X11 -> 85.4 | AB11: =V11-Y11 -> 135.44 | AC11: =W11-Z11 -> 213.15 | AD11: =IF(OR(AND(X11<>0,ABS(AA11)>Assumptions!$B$18*X11),AND(Y11<>0,ABS(AB11)>Assumptions!$B$18*Y11),AND(Z11<>0,ABS(AC11)>Assumptions!$B$18*Z11)),"REVIEW","") -> REVIEW
A12: ='City Data'!A12 -> Andorra la Vella | B12: ='City Data'!B12/Assumptions!$B$2 -> 27.5 | C12: ='City Data'!C12/Assumptions!$B$2 -> 57.5 | D12: ='City Data'!D12/Assumptions!$B$2 -> 120 | E12: =Assumptions!$B$3*Assumptions!$B$4*'City Data'!E12 -> 72 | F12: =Assumptions!$B$3*Assumptions!$B$5*'City Data'!E12 -> 129.6 | G12: =Assumptions!$B$3*Assumptions!$B$6*'City Data'!E12 -> 252 | H12: =Assumptions!$B$7*'City Data'!F12 -> 10 | I12: =Assumptions!$B$8*'City Data'!F12 -> 20 | J12: =Assumptions!$B$9*'City Data'!F12 -> 40 | K12: ='City Data'!G12+'City Data'!H12 -> 3.5 | L12: =IF(AND(Assumptions!$B$13,ISNUMBER('City Data'!I12)),Assumptions!$B$10*'City Data'!I12,0) -> 4.5 | M12: =IF(AND(Assumptions!$B$13,ISNUMBER('City Data'!I12)),Assumptions!$B$11*'City Data'!I12,0) -> 9 | N12: =IF(AND(Assumptions!$B$13,ISNUMBER('City Data'!I12)),Assumptions!$B$12*'City Data'!I12,0) -> 13.5 | O12: =B12+E12+H12+K12 -> 113 | P12: =C12+F12+I12+K12 -> 210.6 | Q12: =D12+G12+J12+K12 -> 415.5 | R12: =IF(Assumptions!$B$14,Assumptions!$B$15*O12,0) -> 11.3 | S12: =IF(Assumptions!$B$14,Assumptions!$B$16*P12,0) -> 42.12 | T12: =IF(Assumptions!$B$14,Assumptions!$B$17*Q12,0) -> 145.425 | U12: =O12+L12+R12 -> 128.8 | V12: =P12+M12+S12 -> 261.72 | W12: =Q12+N12+T12 -> 574.425 | X12: ='City Data'!K12 -> 65 | Y12: ='City Data'!L12 -> 160 | Z12: ='City Data'!M12 -> 465 | AA12: =U12-X12 -> 63.8 | AB12: =V12-Y12 -> 101.72 | AC12: =W12-Z12 -> 109.425 | AD12: =IF(OR(AND(X12<>0,ABS(AA12)>Assumptions!$B$18*X12),AND(Y12<>0,ABS(AB12)>Assumptions!$B$18*Y12),AND(Z12<>0,ABS(AC12)>Assumptions!$B$18*Z12)),"REVIEW","") -> REVIEW
A13: ='City Data'!A13 -> Ankara | B13: ='City Data'!B13/Assumptions!$B$2 -> 10 | C13: ='City Data'!C13/Assumptions!$B$2 -> 27.5 | D13: ='City Data'!D13/Assumptions!$B$2 -> 65 | E13: =Assumptions!$B$3*Assumptions!$B$4*'City Data'!E13 -> 27 | F13: =Assumptions!$B$3*Assumptions!$B$5*'City Data'!E13 -> 48.6 | G13: =Assumptions!$B$3*Assumptions!$B$6*'City Data'!E13 -> 94.5 | H13: =Assumptions!$B$7*'City Data'!F13 -> 5 | I13: =Assumptions!$B$8*'City Data'!F13 -> 10 | J13: =Assumptions!$B$9*'City Data'!F13 -> 20 | K13: ='City Data'!G13+'City Data'!H13 -> 2.6 | L13: =IF(AND(Assumptions!$B$13,ISNUMBER('City Data'!I13)),Assumptions!$B$10*'City Data'!I13,0) -> 3 | M13: =IF(AND(Assumptions!$B$13,ISNUMBER('City Data'!I13)),Assumptions!$B$11*'City Data'!I13,0) -> 6 | N13: =IF(AND(Assumptions!$B$13,ISNUMBER('City Data'!I13)),Assumptions!$B$12*'City Data'!I13,0) -> 9 | O13: =B13+E13+H13+K13 -> 44.6 | P13: =C13+F13+I13+K13 -> 88.7 | Q13: =D13+G13+J13+K13 -> 182.1 | R13: =IF(Assumptions!$B$14,Assumptions!$B$15*O13,0) -> 4.46 | S13: =IF(Assumptions!$B$14,Assumptions!$B$16*P13,0) -> 17.74 | T13: =IF(Assumptions!$B$14,Assumptions!$B$17*Q13,0) -> 63.735 | U13: =O13+L13+R13 -> 52.06 | V13: =P13+M13+S13 -> 112.44 | W13: =Q13+N13+T13 -> 254.835 | X13: ='City Data'!K13 -> 30 | Y13: ='City Data'!L13 -> 75 | Z13: ='City Data'!M13 -> 220 | AA13: =U13-X13 -> 22.06 | AB13: =V13-Y13 -> 37.44 | AC13: =W13-Z13 -> 34.835 | AD13: =IF(OR(AND(X13<>0,ABS(AA13)>Assumptions!$B$18*X13),AND(Y13<>0,ABS(AB13)>Assumptions!$B$18*Y13),AND(Z13<>0,ABS(AC13)>Assumptions!$B$18*Z13)),"REVIEW","") -> REVIEW
... A289: ='City Data'!A289 -> Zurich | B289: ='City Data'!B289/Assumptions!$B$2 -> 70 | C289: ='City Data'!C289/Assumptions!$B$2 -> 125 | D289: ='City Data'!D289/Assumptions!$B$2 -> 275 | E289: =Assumptions!$B$3*Assumptions!$B$4*'City Data'!E289 -> 120 | F289: =Assumptions!$B$3*Assumptions!$B$5*'City Data'!E289 -> 216 | G289: =Assumptions!$B$3*Assumptions!$B$6*'City Data'!E289 -> 420 | H289: =Assumptions!$B$7*'City Data'!F289 -> 40 | I289: =Assumptions!$B$8*'City Data'!F289 -> 80 | J289: =Assumptions!$B$9*'City Data'!F289 -> 160 | K289: ='City Data'!G289+'City Data'!H289 -> 9 | L289: =IF(AND(Assumptions!$B$13,ISNUMBER('City Data'!I289)),Assumptions!$B$10*'City Data'!I289,0) -> 7.5 | M289: =IF(AND(Assumptions!$B$13,ISNUMBER('City Data'!I289)),Assumptions!$B$11*'City Data'!I289,0) -> 15 | N289: =IF(AND(Assumptions!$B$13,ISNUMBER('City Data'!I289)),Assumptions!$B$12*'City Data'!I289,0) -> 22.5 | O289: =B289+E289+H289+K289 -> 239 | P289: =C289+F289+I289+K289 -> 430 | Q289: =D289+G289+J289+K289 -> 864 | R289: =IF(Assumptions!$B$14,Assumptions!$B$15*O289,0) -> 23.9 | S289: =IF(Assumptions!$B$14,Assumptions!$B$16*P289,0) -> 86 | T289: =IF(Assumptions!$B$14,Assumptions!$B$17*Q289,0) -> 302.4 | U289: =O289+L289+R289 -> 270.4 | V289: =P289+M289+S289 -> 531 | W289: =Q289+N289+T289 -> 1188.9 | X289: ='City Data'!K289 -> 130 | Y289: ='City Data'!L289 -> 300 | Z289: ='City Data'!M289 -> 850 | AA289: =U289-X289 -> 140.4 | AB289: =V289-Y289 -> 231 | AC289: =W289-Z289 -> 338.9 | AD289: =IF(OR(AND(X289<>0,ABS(AA289)>Assumptions!$B$18*X289),AND(Y289<>0,ABS(AB289)>Assumptions!$B$18*Y289),AND(Z289<>0,ABS(AC289)>Assumptions!$B$18*Z289)),"REVIEW","") -> REVIEW
