Workbook

Sheet Assumptions
A1: Daily Cost Estimator — assumptions (mirrors computeDailyTiers() in city.html)
A2: Edit the yellow cells; the Cities sheet recalculates automatically.
A3: Assumption | B3: Value | C3: Notes
A4: Meal multiplier — Budget | B4: 1 | C4: x cost.meal, x3 meals/day
A5: Meal multiplier — Mid | B5: 1.8 | C5: x cost.meal, x3 meals/day
A6: Meal multiplier — Luxury | B6: 3.5 | C6: x cost.meal, x3 meals/day
A7: Transport trips/day — Budget | B7: 1 | C7: x cost.taxi
A8: Transport trips/day — Mid | B8: 2 | C8: x cost.taxi
A9: Transport trips/day — Luxury | B9: 4 | C9: x cost.taxi
A10: Alcoholic drinks/day — Budget | B10: 1 | C10: x drink price (only if beer is a number)
A11: Alcoholic drinks/day — Mid | B11: 2 | C11: x drink price
A12: Alcoholic drinks/day — Luxury | B12: 3 | C12: x drink price
A13: Alcohol drink price multiplier | B13: 1.5 | C13: x average beer price -- covers cocktails/wine/spirits running pricier than beer
A14: Activities % — Budget | B14: 0.1 | C14: of core subtotal (hotel+meals+transport+coffee+water)
A15: Activities % — Mid | B15: 0.2 | C15: of core subtotal
A16: Activities % — Luxury | B16: 0.35 | C16: of core subtotal
A17: Include alcoholic beverages | B17: =TRUE() -> TRUE | C17: global toggle — matches the live page's checkbox default
A18: Include activities/tours | B18: =TRUE() -> TRUE | C18: global toggle — matches the live page's checkbox default
A19: Review-flag threshold (% diff) | B19: 0.25 | C19: flag a city if new mid vs old mid differ by more than this

Sheet Cities
A1: City | B1: Beer status | C1: Hotel budget | D1: Hotel mid | E1: Hotel luxury | F1: Meal price | G1: Taxi price | H1: Coffee | I1: Water | J1: Beer (numeric) | K1: Core Budget | L1: Core Mid | M1: Core Luxury | N1: Alcohol Budget | O1: Alcohol Mid | P1: Alcohol Luxury | Q1: Activities Budget | R1: Activities Mid | S1: Activities Luxury | T1: NEW Total Budget | U1: NEW Total Mid | V1: NEW Total Luxury | W1: OLD site Budget | X1: OLD site Mid | Y1: OLD site Luxury | Z1: Mid $ delta (new-old) | AA1: Mid % diff | AB1: Flag
A2: Abidjan | C2: 35 | D2: 75 | E2: 220 | F2: 15 | G2: 7 | H2: 2.5 | I2: 0.8 | J2: 3 | K2: =C2+3*Assumptions!$B$4*F2+Assumptions!$B$7*G2+H2+I2 -> 90.3 | L2: =D2+3*Assumptions!$B$5*F2+Assumptions!$B$8*G2+H2+I2 -> 173.3 | M2: =E2+3*Assumptions!$B$6*F2+Assumptions!$B$9*G2+H2+I2 -> 408.8 | N2: =IF(AND(Assumptions!$B$17,ISNUMBER(J2)),Assumptions!$B$10*Assumptions!$B$13*J2,0) -> 4.5 | O2: =IF(AND(Assumptions!$B$17,ISNUMBER(J2)),Assumptions!$B$11*Assumptions!$B$13*J2,0) -> 9 | P2: =IF(AND(Assumptions!$B$17,ISNUMBER(J2)),Assumptions!$B$12*Assumptions!$B$13*J2,0) -> 13.5 | Q2: =IF(Assumptions!$B$18,Assumptions!$B$14*K2,0) -> 9.03 | R2: =IF(Assumptions!$B$18,Assumptions!$B$15*L2,0) -> 34.66 | S2: =IF(Assumptions!$B$18,Assumptions!$B$16*M2,0) -> 143.08 | T2: =K2+N2+Q2 -> 103.83 | U2: =L2+O2+R2 -> 216.96 | V2: =M2+P2+S2 -> 565.38 | W2: 50 | X2: 120 | Y2: 355 | Z2: =U2-X2 -> 96.96 | AA2: =IFERROR((U2-X2)/X2,"") -> 0.808 | AB2: =IF(ISNUMBER(AA2),IF(ABS(AA2)>Assumptions!$B$19,"REVIEW",""),"") -> REVIEW
A3: Abu Dhabi | B3: restricted | C3: 75 | D3: 140 | E3: 400 | F3: 30 | G3: 15 | H3: 5 | I3: 1 | K3: =C3+3*Assumptions!$B$4*F3+Assumptions!$B$7*G3+H3+I3 -> 186 | L3: =D3+3*Assumptions!$B$5*F3+Assumptions!$B$8*G3+H3+I3 -> 338 | M3: =E3+3*Assumptions!$B$6*F3+Assumptions!$B$9*G3+H3+I3 -> 781 | N3: =IF(AND(Assumptions!$B$17,ISNUMBER(J3)),Assumptions!$B$10*Assumptions!$B$13*J3,0) -> 0 | O3: =IF(AND(Assumptions!$B$17,ISNUMBER(J3)),Assumptions!$B$11*Assumptions!$B$13*J3,0) -> 0 | P3: =IF(AND(Assumptions!$B$17,ISNUMBER(J3)),Assumptions!$B$12*Assumptions!$B$13*J3,0) -> 0 | Q3: =IF(Assumptions!$B$18,Assumptions!$B$14*K3,0) -> 18.6 | R3: =IF(Assumptions!$B$18,Assumptions!$B$15*L3,0) -> 67.6 | S3: =IF(Assumptions!$B$18,Assumptions!$B$16*M3,0) -> 273.35 | T3: =K3+N3+Q3 -> 204.6 | U3: =L3+O3+R3 -> 405.6 | V3: =M3+P3+S3 -> 1054.35 | W3: 70 | X3: 185 | Y3: 600 | Z3: =U3-X3 -> 220.6 | AA3: =IFERROR((U3-X3)/X3,"") -> 1.1924324 | AB3: =IF(ISNUMBER(AA3),IF(ABS(AA3)>Assumptions!$B$19,"REVIEW",""),"") -> REVIEW
A4: Accra | C4: 30 | D4: 90 | E4: 280 | F4: 12 | G4: 5 | H4: 3 | I4: 0.8 | J4: 2.5 | K4: =C4+3*Assumptions!$B$4*F4+Assumptions!$B$7*G4+H4+I4 -> 74.8 | L4: =D4+3*Assumptions!$B$5*F4+Assumptions!$B$8*G4+H4+I4 -> 168.6 | M4: =E4+3*Assumptions!$B$6*F4+Assumptions!$B$9*G4+H4+I4 -> 429.8 | N4: =IF(AND(Assumptions!$B$17,ISNUMBER(J4)),Assumptions!$B$10*Assumptions!$B$13*J4,0) -> 3.75 | O4: =IF(AND(Assumptions!$B$17,ISNUMBER(J4)),Assumptions!$B$11*Assumptions!$B$13*J4,0) -> 7.5 | P4: =IF(AND(Assumptions!$B$17,ISNUMBER(J4)),Assumptions!$B$12*Assumptions!$B$13*J4,0) -> 11.25 | Q4: =IF(Assumptions!$B$18,Assumptions!$B$14*K4,0) -> 7.48 | R4: =IF(Assumptions!$B$18,Assumptions!$B$15*L4,0) -> 33.72 | S4: =IF(Assumptions!$B$18,Assumptions!$B$16*M4,0) -> 150.43 | T4: =K4+N4+Q4 -> 86.03 | U4: =L4+O4+R4 -> 209.82 | V4: =M4+P4+S4 -> 591.48 | W4: 45 | X4: 115 | Y4: 350 | Z4: =U4-X4 -> 94.82 | AA4: =IFERROR((U4-X4)/X4,"") -> 0.82452174 | AB4: =IF(ISNUMBER(AA4),IF(ABS(AA4)>Assumptions!$B$19,"REVIEW",""),"") -> REVIEW
A5: Addis Ababa | C5: 15 | D5: 70 | E5: 280 | F5: 8 | G5: 4 | H5: 1.05 | I5: 0.49 | J5: 0.95 | K5: =C5+3*Assumptions!$B$4*F5+Assumptions!$B$7*G5+H5+I5 -> 44.54 | L5: =D5+3*Assumptions!$B$5*F5+Assumptions!$B$8*G5+H5+I5 -> 122.74 | M5: =E5+3*Assumptions!$B$6*F5+Assumptions!$B$9*G5+H5+I5 -> 381.54 | N5: =IF(AND(Assumptions!$B$17,ISNUMBER(J5)),Assumptions!$B$10*Assumptions!$B$13*J5,0) -> 1.425 | O5: =IF(AND(Assumptions!$B$17,ISNUMBER(J5)),Assumptions!$B$11*Assumptions!$B$13*J5,0) -> 2.85 | P5: =IF(AND(Assumptions!$B$17,ISNUMBER(J5)),Assumptions!$B$12*Assumptions!$B$13*J5,0) -> 4.275 | Q5: =IF(Assumptions!$B$18,Assumptions!$B$14*K5,0) -> 4.454 | R5: =IF(Assumptions!$B$18,Assumptions!$B$15*L5,0) -> 24.548 | S5: =IF(Assumptions!$B$18,Assumptions!$B$16*M5,0) -> 133.539 | T5: =K5+N5+Q5 -> 50.419 | U5: =L5+O5+R5 -> 150.138 | V5: =M5+P5+S5 -> 519.354 | W5: 35 | X5: 90 | Y5: 295 | Z5: =U5-X5 -> 60.138 | AA5: =IFERROR((U5-X5)/X5,"") -> 0.6682 | AB5: =IF(ISNUMBER(AA5),IF(ABS(AA5)>Assumptions!$B$19,"REVIEW",""),"") -> REVIEW
A6: Ahmedabad | C6: 15 | D6: 40 | E6: 110 | F6: 4 | G6: 3 | H6: 1.5 | I6: 0.3 | J6: 6 | K6: =C6+3*Assumptions!$B$4*F6+Assumptions!$B$7*G6+H6+I6 -> 31.8 | L6: =D6+3*Assumptions!$B$5*F6+Assumptions!$B$8*G6+H6+I6 -> 69.4 | M6: =E6+3*Assumptions!$B$6*F6+Assumptions!$B$9*G6+H6+I6 -> 165.8 | N6: =IF(AND(Assumptions!$B$17,ISNUMBER(J6)),Assumptions!$B$10*Assumptions!$B$13*J6,0) -> 9 | O6: =IF(AND(Assumptions!$B$17,ISNUMBER(J6)),Assumptions!$B$11*Assumptions!$B$13*J6,0) -> 18 | P6: =IF(AND(Assumptions!$B$17,ISNUMBER(J6)),Assumptions!$B$12*Assumptions!$B$13*J6,0) -> 27 | Q6: =IF(Assumptions!$B$18,Assumptions!$B$14*K6,0) -> 3.18 | R6: =IF(Assumptions!$B$18,Assumptions!$B$15*L6,0) -> 13.88 | S6: =IF(Assumptions!$B$18,Assumptions!$B$16*M6,0) -> 58.03 | T6: =K6+N6+Q6 -> 43.98 | U6: =L6+O6+R6 -> 101.28 | V6: =M6+P6+S6 -> 250.83 | W6: 25 | X6: 60 | Y6: 180 | Z6: =U6-X6 -> 41.28 | AA6: =IFERROR((U6-X6)/X6,"") -> 0.688 | AB6: =IF(ISNUMBER(AA6),IF(ABS(AA6)>Assumptions!$B$19,"REVIEW",""),"") -> REVIEW
A7: Alexandria | C7: 20 | D7: 70 | E7: 180 | F7: 6 | G7: 3 | H7: 1.5 | I7: 0.4 | J7: 3 | K7: =C7+3*Assumptions!$B$4*F7+Assumptions!$B$7*G7+H7+I7 -> 42.9 | L7: =D7+3*Assumptions!$B$5*F7+Assumptions!$B$8*G7+H7+I7 -> 110.3 | M7: =E7+3*Assumptions!$B$6*F7+Assumptions!$B$9*G7+H7+I7 -> 256.9 | N7: =IF(AND(Assumptions!$B$17,ISNUMBER(J7)),Assumptions!$B$10*Assumptions!$B$13*J7,0) -> 4.5 | O7: =IF(AND(Assumptions!$B$17,ISNUMBER(J7)),Assumptions!$B$11*Assumptions!$B$13*J7,0) -> 9 | P7: =IF(AND(Assumptions!$B$17,ISNUMBER(J7)),Assumptions!$B$12*Assumptions!$B$13*J7,0) -> 13.5 | Q7: =IF(Assumptions!$B$18,Assumptions!$B$14*K7,0) -> 4.29 | R7: =IF(Assumptions!$B$18,Assumptions!$B$15*L7,0) -> 22.06 | S7: =IF(Assumptions!$B$18,Assumptions!$B$16*M7,0) -> 89.915 | T7: =K7+N7+Q7 -> 51.69 | U7: =L7+O7+R7 -> 141.36 | V7: =M7+P7+S7 -> 360.315 | W7: 30 | X7: 75 | Y7: 250 | Z7: =U7-X7 -> 66.36 | AA7: =IFERROR((U7-X7)/X7,"") -> 0.8848 | AB7: =IF(ISNUMBER(AA7),IF(ABS(AA7)>Assumptions!$B$19,"REVIEW",""),"") -> REVIEW
A8: Algiers | C8: 35 | D8: 65 | E8: 180 | F8: 9 | G8: 5 | H8: 1.3 | I8: 0.5 | J8: 4 | K8: =C8+3*Assumptions!$B$4*F8+Assumptions!$B$7*G8+H8+I8 -> 68.8 | L8: =D8+3*Assumptions!$B$5*F8+Assumptions!$B$8*G8+H8+I8 -> 125.4 | M8: =E8+3*Assumptions!$B$6*F8+Assumptions!$B$9*G8+H8+I8 -> 296.3 | N8: =IF(AND(Assumptions!$B$17,ISNUMBER(J8)),Assumptions!$B$10*Assumptions!$B$13*J8,0) -> 6 | O8: =IF(AND(Assumptions!$B$17,ISNUMBER(J8)),Assumptions!$B$11*Assumptions!$B$13*J8,0) -> 12 | P8: =IF(AND(Assumptions!$B$17,ISNUMBER(J8)),Assumptions!$B$12*Assumptions!$B$13*J8,0) -> 18 | Q8: =IF(Assumptions!$B$18,Assumptions!$B$14*K8,0) -> 6.88 | R8: =IF(Assumptions!$B$18,Assumptions!$B$15*L8,0) -> 25.08 | S8: =IF(Assumptions!$B$18,Assumptions!$B$16*M8,0) -> 103.705 | T8: =K8+N8+Q8 -> 81.68 | U8: =L8+O8+R8 -> 162.48 | V8: =M8+P8+S8 -> 418.005 | W8: 40 | X8: 100 | Y8: 285 | Z8: =U8-X8 -> 62.48 | AA8: =IFERROR((U8-X8)/X8,"") -> 0.6248 | AB8: =IF(ISNUMBER(AA8),IF(ABS(AA8)>Assumptions!$B$19,"REVIEW",""),"") -> REVIEW
A9: Almaty | C9: 25 | D9: 72 | E9: 220 | F9: 15 | G9: 4 | H9: 2.4 | I9: 0.5 | J9: 2 | K9: =C9+3*Assumptions!$B$4*F9+Assumptions!$B$7*G9+H9+I9 -> 76.9 | L9: =D9+3*Assumptions!$B$5*F9+Assumptions!$B$8*G9+H9+I9 -> 163.9 | M9: =E9+3*Assumptions!$B$6*F9+Assumptions!$B$9*G9+H9+I9 -> 396.4 | N9: =IF(AND(Assumptions!$B$17,ISNUMBER(J9)),Assumptions!$B$10*Assumptions!$B$13*J9,0) -> 3 | O9: =IF(AND(Assumptions!$B$17,ISNUMBER(J9)),Assumptions!$B$11*Assumptions!$B$13*J9,0) -> 6 | P9: =IF(AND(Assumptions!$B$17,ISNUMBER(J9)),Assumptions!$B$12*Assumptions!$B$13*J9,0) -> 9 | Q9: =IF(Assumptions!$B$18,Assumptions!$B$14*K9,0) -> 7.69 | R9: =IF(Assumptions!$B$18,Assumptions!$B$15*L9,0) -> 32.78 | S9: =IF(Assumptions!$B$18,Assumptions!$B$16*M9,0) -> 138.74 | T9: =K9+N9+Q9 -> 87.59 | U9: =L9+O9+R9 -> 202.68 | V9: =M9+P9+S9 -> 544.14 | W9: 45 | X9: 110 | Y9: 335 | Z9: =U9-X9 -> 92.68 | AA9: =IFERROR((U9-X9)/X9,"") -> 0.84254545 | AB9: =IF(ISNUMBER(AA9),IF(ABS(AA9)>Assumptions!$B$19,"REVIEW",""),"") -> REVIEW
A10: Amman | C10: 40 | D10: 90 | E10: 220 | F10: 18 | G10: 5 | H10: 3 | I10: 1 | J10: 7 | K10: =C10+3*Assumptions!$B$4*F10+Assumptions!$B$7*G10+H10+I10 -> 103 | L10: =D10+3*Assumptions!$B$5*F10+Assumptions!$B$8*G10+H10+I10 -> 201.2 | M10: =E10+3*Assumptions!$B$6*F10+Assumptions!$B$9*G10+H10+I10 -> 433 | N10: =IF(AND(Assumptions!$B$17,ISNUMBER(J10)),Assumptions!$B$10*Assumptions!$B$13*J10,0) -> 10.5 | O10: =IF(AND(Assumptions!$B$17,ISNUMBER(J10)),Assumptions!$B$11*Assumptions!$B$13*J10,0) -> 21 | P10: =IF(AND(Assumptions!$B$17,ISNUMBER(J10)),Assumptions!$B$12*Assumptions!$B$13*J10,0) -> 31.5 | Q10: =IF(Assumptions!$B$18,Assumptions!$B$14*K10,0) -> 10.3 | R10: =IF(Assumptions!$B$18,Assumptions!$B$15*L10,0) -> 40.24 | S10: =IF(Assumptions!$B$18,Assumptions!$B$16*M10,0) -> 151.55 | T10: =K10+N10+Q10 -> 123.8 | U10: =L10+O10+R10 -> 262.44 | V10: =M10+P10+S10 -> 616.05 | W10: 50 | X10: 130 | Y10: 385 | Z10: =U10-X10 -> 132.44 | AA10: =IFERROR((U10-X10)/X10,"") -> 1.0187692 | AB10: =IF(ISNUMBER(AA10),IF(ABS(AA10)>Assumptions!$B$19,"REVIEW",""),"") -> REVIEW
A11: Amsterdam | C11: 80 | D11: 160 | E11: 380 | F11: 28 | G11: 25 | H11: 3.5 | I11: 1.5 | J11: 6 | K11: =C11+3*Assumptions!$B$4*F11+Assumptions!$B$7*G11+H11+I11 -> 194 | L11: =D11+3*Assumptions!$B$5*F11+Assumptions!$B$8*G11+H11+I11 -> 366.2 | M11: =E11+3*Assumptions!$B$6*F11+Assumptions!$B$9*G11+H11+I11 -> 779 | N11: =IF(AND(Assumptions!$B$17,ISNUMBER(J11)),Assumptions!$B$10*Assumptions!$B$13*J11,0) -> 9 | O11: =IF(AND(Assumptions!$B$17,ISNUMBER(J11)),Assumptions!$B$11*Assumptions!$B$13*J11,0) -> 18 | P11: =IF(AND(Assumptions!$B$17,ISNUMBER(J11)),Assumptions!$B$12*Assumptions!$B$13*J11,0) -> 27 | Q11: =IF(Assumptions!$B$18,Assumptions!$B$14*K11,0) -> 19.4 | R11: =IF(Assumptions!$B$18,Assumptions!$B$15*L11,0) -> 73.24 | S11: =IF(Assumptions!$B$18,Assumptions!$B$16*M11,0) -> 272.65 | T11: =K11+N11+Q11 -> 222.4 | U11: =L11+O11+R11 -> 457.44 | V11: =M11+P11+S11 -> 1078.65 | W11: 90 | X11: 220 | Y11: 600 | Z11: =U11-X11 -> 237.44 | AA11: =IFERROR((U11-X11)/X11,"") -> 1.0792727 | AB11: =IF(ISNUMBER(AA11),IF(ABS(AA11)>Assumptions!$B$19,"REVIEW",""),"") -> REVIEW
A12: Andorra la Vella | C12: 55 | D12: 115 | E12: 240 | F12: 24 | G12: 10 | H12: 2.2 | I12: 1.3 | J12: 4.5 | K12: =C12+3*Assumptions!$B$4*F12+Assumptions!$B$7*G12+H12+I12 -> 140.5 | L12: =D12+3*Assumptions!$B$5*F12+Assumptions!$B$8*G12+H12+I12 -> 268.1 | M12: =E12+3*Assumptions!$B$6*F12+Assumptions!$B$9*G12+H12+I12 -> 535.5 | N12: =IF(AND(Assumptions!$B$17,ISNUMBER(J12)),Assumptions!$B$10*Assumptions!$B$13*J12,0) -> 6.75 | O12: =IF(AND(Assumptions!$B$17,ISNUMBER(J12)),Assumptions!$B$11*Assumptions!$B$13*J12,0) -> 13.5 | P12: =IF(AND(Assumptions!$B$17,ISNUMBER(J12)),Assumptions!$B$12*Assumptions!$B$13*J12,0) -> 20.25 | Q12: =IF(Assumptions!$B$18,Assumptions!$B$14*K12,0) -> 14.05 | R12: =IF(Assumptions!$B$18,Assumptions!$B$15*L12,0) -> 53.62 | S12: =IF(Assumptions!$B$18,Assumptions!$B$16*M12,0) -> 187.425 | T12: =K12+N12+Q12 -> 161.3 | U12: =L12+O12+R12 -> 335.22 | V12: =M12+P12+S12 -> 743.175 | W12: 65 | X12: 160 | Y12: 465 | Z12: =U12-X12 -> 175.22 | AA12: =IFERROR((U12-X12)/X12,"") -> 1.095125 | AB12: =IF(ISNUMBER(AA12),IF(ABS(AA12)>Assumptions!$B$19,"REVIEW",""),"") -> REVIEW
A13: Ankara | C13: 20 | D13: 55 | E13: 130 | F13: 9 | G13: 5 | H13: 2.2 | I13: 0.4 | J13: 3 | K13: =C13+3*Assumptions!$B$4*F13+Assumptions!$B$7*G13+H13+I13 -> 54.6 | L13: =D13+3*Assumptions!$B$5*F13+Assumptions!$B$8*G13+H13+I13 -> 116.2 | M13: =E13+3*Assumptions!$B$6*F13+Assumptions!$B$9*G13+H13+I13 -> 247.1 | N13: =IF(AND(Assumptions!$B$17,ISNUMBER(J13)),Assumptions!$B$10*Assumptions!$B$13*J13,0) -> 4.5 | O13: =IF(AND(Assumptions!$B$17,ISNUMBER(J13)),Assumptions!$B$11*Assumptions!$B$13*J13,0) -> 9 | P13: =IF(AND(Assumptions!$B$17,ISNUMBER(J13)),Assumptions!$B$12*Assumptions!$B$13*J13,0) -> 13.5 | Q13: =IF(Assumptions!$B$18,Assumptions!$B$14*K13,0) -> 5.46 | R13: =IF(Assumptions!$B$18,Assumptions!$B$15*L13,0) -> 23.24 | S13: =IF(Assumptions!$B$18,Assumptions!$B$16*M13,0) -> 86.485 | T13: =K13+N13+Q13 -> 64.56 | U13: =L13+O13+R13 -> 148.44 | V13: =M13+P13+S13 -> 347.085 | W13: 30 | X13: 75 | Y13: 220 | Z13: =U13-X13 -> 73.44 | AA13: =IFERROR((U13-X13)/X13,"") -> 0.9792 | AB13: =IF(ISNUMBER(AA13),IF(ABS(AA13)>Assumptions!$B$19,"REVIEW",""),"") -> REVIEW
A14: Antalya | C14: 25 | D14: 55 | E14: 160 | F14: 12 | G14: 7 | H14: 3 | I14: 0.4 | J14: 4 | K14: =C14+3*Assumptions!$B$4*F14+Assumptions!$B$7*G14+H14+I14 -> 71.4 | L14: =D14+3*Assumptions!$B$5*F14+Assumptions!$B$8*G14+H14+I14 -> 137.2 | M14: =E14+3*Assumptions!$B$6*F14+Assumptions!$B$9*G14+H14+I14 -> 317.4 | N14: =IF(AND(Assumptions!$B$17,ISNUMBER(J14)),Assumptions!$B$10*Assumptions!$B$13*J14,0) -> 6 | O14: =IF(AND(Assumptions!$B$17,ISNUMBER(J14)),Assumptions!$B$11*Assumptions!$B$13*J14,0) -> 12 | P14: =IF(AND(Assumptions!$B$17,ISNUMBER(J14)),Assumptions!$B$12*Assumptions!$B$13*J14,0) -> 18 | Q14: =IF(Assumptions!$B$18,Assumptions!$B$14*K14,0) -> 7.14 | R14: =IF(Assumptions!$B$18,Assumptions!$B$15*L14,0) -> 27.44 | S14: =IF(Assumptions!$B$18,Assumptions!$B$16*M14,0) -> 111.09 | T14: =K14+N14+Q14 -> 84.54 | U14: =L14+O14+R14 -> 176.64 | V14: =M14+P14+S14 -> 446.49 | W14: 40 | X14: 95 | Y14: 280 | Z14: =U14-X14 -> 81.64 | AA14: =IFERROR((U14-X14)/X14,"") -> 0.85936842 | AB14: =IF(ISNUMBER(AA14),IF(ABS(AA14)>Assumptions!$B$19,"REVIEW",""),"") -> REVIEW
A15: Antananarivo | C15: 20 | D15: 55 | E15: 150 | F15: 8 | G15: 4 | H15: 1.5 | I15: 0.5 | J15: 2 | K15: =C15+3*Assumptions!$B$4*F15+Assumptions!$B$7*G15+H15+I15 -> 50 | L15: =D15+3*Assumptions!$B$5*F15+Assumptions!$B$8*G15+H15+I15 -> 108.2 | M15: =E15+3*Assumptions!$B$6*F15+Assumptions!$B$9*G15+H15+I15 -> 252 | N15: =IF(AND(Assumptions!$B$17,ISNUMBER(J15)),Assumptions!$B$10*Assumptions!$B$13*J15,0) -> 3 | O15: =IF(AND(Assumptions!$B$17,ISNUMBER(J15)),Assumptions!$B$11*Assumptions!$B$13*J15,0) -> 6 | P15: =IF(AND(Assumptions!$B$17,ISNUMBER(J15)),Assumptions!$B$12*Assumptions!$B$13*J15,0) -> 9 | Q15: =IF(Assumptions!$B$18,Assumptions!$B$14*K15,0) -> 5 | R15: =IF(Assumptions!$B$18,Assumptions!$B$15*L15,0) -> 21.64 | S15: =IF(Assumptions!$B$18,Assumptions!$B$16*M15,0) -> 88.2 | T15: =K15+N15+Q15 -> 58 | U15: =L15+O15+R15 -> 135.84 | V15: =M15+P15+S15 -> 349.2 | W15: 35 | X15: 80 | Y15: 245 | Z15: =U15-X15 -> 55.84 | AA15: =IFERROR((U15-X15)/X15,"") -> 0.698 | AB15: =IF(ISNUMBER(AA15),IF(ABS(AA15)>Assumptions!$B$19,"REVIEW",""),"") -> REVIEW
... A24: Bamako | C24: 28 | D24: 90 | E24: 180 | F24: 12 | G24: 4 | H24: 2 | I24: 0.7 | J24: 3 | K24: =C24+3*Assumptions!$B$4*F24+Assumptions!$B$7*G24+H24+I24 -> 70.7 | L24: =D24+3*Assumptions!$B$5*F24+Assumptions!$B$8*G24+H24+I24 -> 165.5 | M24: =E24+3*Assumptions!$B$6*F24+Assumptions!$B$9*G24+H24+I24 -> 324.7 | N24: =IF(AND(Assumptions!$B$17,ISNUMBER(J24)),Assumptions!$B$10*Assumptions!$B$13*J24,0) -> 4.5 | O24: =IF(AND(Assumptions!$B$17,ISNUMBER(J24)),Assumptions!$B$11*Assumptions!$B$13*J24,0) -> 9 | P24: =IF(AND(Assumptions!$B$17,ISNUMBER(J24)),Assumptions!$B$12*Assumptions!$B$13*J24,0) -> 13.5 | Q24: =IF(Assumptions!$B$18,Assumptions!$B$14*K24,0) -> 7.07 | R24: =IF(Assumptions!$B$18,Assumptions!$B$15*L24,0) -> 33.1 | S24: =IF(Assumptions!$B$18,Assumptions!$B$16*M24,0) -> 113.645 | T24: =K24+N24+Q24 -> 82.27 | U24: =L24+O24+R24 -> 207.6 | V24: =M24+P24+S24 -> 451.845 | W24: 40 | X24: 100 | Y24: 300 | Z24: =U24-X24 -> 107.6 | AA24: =IFERROR((U24-X24)/X24,"") -> 1.076 | AB24: =IF(ISNUMBER(AA24),IF(ABS(AA24)>Assumptions!$B$19,"REVIEW",""),"") -> REVIEW
A25: Bandar Seri Begawan | B25: restricted | C25: 25 | D25: 75 | E25: 150 | F25: 12 | G25: 10 | H25: 3 | I25: 1 | K25: =C25+3*Assumptions!$B$4*F25+Assumptions!$B$7*G25+H25+I25 -> 75 | L25: =D25+3*Assumptions!$B$5*F25+Assumptions!$B$8*G25+H25+I25 -> 163.8 | M25: =E25+3*Assumptions!$B$6*F25+Assumptions!$B$9*G25+H25+I25 -> 320 | N25: =IF(AND(Assumptions!$B$17,ISNUMBER(J25)),Assumptions!$B$10*Assumptions!$B$13*J25,0) -> 0 | O25: =IF(AND(Assumptions!$B$17,ISNUMBER(J25)),Assumptions!$B$11*Assumptions!$B$13*J25,0) -> 0 | P25: =IF(AND(Assumptions!$B$17,ISNUMBER(J25)),Assumptions!$B$12*Assumptions!$B$13*J25,0) -> 0 | Q25: =IF(Assumptions!$B$18,Assumptions!$B$14*K25,0) -> 7.5 | R25: =IF(Assumptions!$B$18,Assumptions!$B$15*L25,0) -> 32.76 | S25: =IF(Assumptions!$B$18,Assumptions!$B$16*M25,0) -> 112 | T25: =K25+N25+Q25 -> 82.5 | U25: =L25+O25+R25 -> 196.56 | V25: =M25+P25+S25 -> 432 | W25: 40 | X25: 100 | Y25: 285 | Z25: =U25-X25 -> 96.56 | AA25: =IFERROR((U25-X25)/X25,"") -> 0.9656 | AB25: =IF(ISNUMBER(AA25),IF(ABS(AA25)>Assumptions!$B$19,"REVIEW",""),"") -> REVIEW
A26: Bangkok | C26: 18 | D26: 45 | E26: 150 | F26: 8 | G26: 5 | H26: 2.5 | I26: 0.5 | J26: 3 | K26: =C26+3*Assumptions!$B$4*F26+Assumptions!$B$7*G26+H26+I26 -> 50 | L26: =D26+3*Assumptions!$B$5*F26+Assumptions!$B$8*G26+H26+I26 -> 101.2 | M26: =E26+3*Assumptions!$B$6*F26+Assumptions!$B$9*G26+H26+I26 -> 257 | N26: =IF(AND(Assumptions!$B$17,ISNUMBER(J26)),Assumptions!$B$10*Assumptions!$B$13*J26,0) -> 4.5 | O26: =IF(AND(Assumptions!$B$17,ISNUMBER(J26)),Assumptions!$B$11*Assumptions!$B$13*J26,0) -> 9 | P26: =IF(AND(Assumptions!$B$17,ISNUMBER(J26)),Assumptions!$B$12*Assumptions!$B$13*J26,0) -> 13.5 | Q26: =IF(Assumptions!$B$18,Assumptions!$B$14*K26,0) -> 5 | R26: =IF(Assumptions!$B$18,Assumptions!$B$15*L26,0) -> 20.24 | S26: =IF(Assumptions!$B$18,Assumptions!$B$16*M26,0) -> 89.95 | T26: =K26+N26+Q26 -> 59.5 | U26: =L26+O26+R26 -> 130.44 | V26: =M26+P26+S26 -> 360.45 | W26: 35 | X26: 90 | Y26: 250 | Z26: =U26-X26 -> 40.44 | AA26: =IFERROR((U26-X26)/X26,"") -> 0.44933333 | AB26: =IF(ISNUMBER(AA26),IF(ABS(AA26)>Assumptions!$B$19,"REVIEW",""),"") -> REVIEW
A27: Bangui | C27: 30 | D27: 70 | E27: 200 | F27: 12 | G27: 4 | H27: 2.5 | I27: 1 | J27: 2 | K27: =C27+3*Assumptions!$B$4*F27+Assumptions!$B$7*G27+H27+I27 -> 73.5 | L27: =D27+3*Assumptions!$B$5*F27+Assumptions!$B$8*G27+H27+I27 -> 146.3 | M27: =E27+3*Assumptions!$B$6*F27+Assumptions!$B$9*G27+H27+I27 -> 345.5 | N27: =IF(AND(Assumptions!$B$17,ISNUMBER(J27)),Assumptions!$B$10*Assumptions!$B$13*J27,0) -> 3 | O27: =IF(AND(Assumptions!$B$17,ISNUMBER(J27)),Assumptions!$B$11*Assumptions!$B$13*J27,0) -> 6 | P27: =IF(AND(Assumptions!$B$17,ISNUMBER(J27)),Assumptions!$B$12*Assumptions!$B$13*J27,0) -> 9 | Q27: =IF(Assumptions!$B$18,Assumptions!$B$14*K27,0) -> 7.35 | R27: =IF(Assumptions!$B$18,Assumptions!$B$15*L27,0) -> 29.26 | S27: =IF(Assumptions!$B$18,Assumptions!$B$16*M27,0) -> 120.925 | T27: =K27+N27+Q27 -> 83.85 | U27: =L27+O27+R27 -> 181.56 | V27: =M27+P27+S27 -> 475.425 | W27: 40 | X27: 105 | Y27: 310 | Z27: =U27-X27 -> 76.56 | AA27: =IFERROR((U27-X27)/X27,"") -> 0.72914286 | AB27: =IF(ISNUMBER(AA27),IF(ABS(AA27)>Assumptions!$B$19,"REVIEW",""),"") -> REVIEW
A28: Banjul | C28: 25 | D28: 55 | E28: 150 | F28: 8 | G28: 6 | H28: 2.5 | I28: 0.6 | J28: 3 | K28: =C28+3*Assumptions!$B$4*F28+Assumptions!$B$7*G28+H28+I28 -> 58.1 | L28: =D28+3*Assumptions!$B$5*F28+Assumptions!$B$8*G28+H28+I28 -> 113.3 | M28: =E28+3*Assumptions!$B$6*F28+Assumptions!$B$9*G28+H28+I28 -> 261.1 | N28: =IF(AND(Assumptions!$B$17,ISNUMBER(J28)),Assumptions!$B$10*Assumptions!$B$13*J28,0) -> 4.5 | O28: =IF(AND(Assumptions!$B$17,ISNUMBER(J28)),Assumptions!$B$11*Assumptions!$B$13*J28,0) -> 9 | P28: =IF(AND(Assumptions!$B$17,ISNUMBER(J28)),Assumptions!$B$12*Assumptions!$B$13*J28,0) -> 13.5 | Q28: =IF(Assumptions!$B$18,Assumptions!$B$14*K28,0) -> 5.81 | R28: =IF(Assumptions!$B$18,Assumptions!$B$15*L28,0) -> 22.66 | S28: =IF(Assumptions!$B$18,Assumptions!$B$16*M28,0) -> 91.385 | T28: =K28+N28+Q28 -> 68.41 | U28: =L28+O28+R28 -> 144.96 | V28: =M28+P28+S28 -> 365.985 | W28: 35 | X28: 85 | Y28: 250 | Z28: =U28-X28 -> 59.96 | AA28: =IFERROR((U28-X28)/X28,"") -> 0.70541176 | AB28: =IF(ISNUMBER(AA28),IF(ABS(AA28)>Assumptions!$B$19,"REVIEW",""),"") -> REVIEW
A29: Barcelona | C29: 55 | D29: 120 | E29: 300 | F29: 22 | G29: 15 | H29: 2 | I29: 1 | J29: 3.5 | K29: =C29+3*Assumptions!$B$4*F29+Assumptions!$B$7*G29+H29+I29 -> 139 | L29: =D29+3*Assumptions!$B$5*F29+Assumptions!$B$8*G29+H29+I29 -> 271.8 | M29: =E29+3*Assumptions!$B$6*F29+Assumptions!$B$9*G29+H29+I29 -> 594 | N29: =IF(AND(Assumptions!$B$17,ISNUMBER(J29)),Assumptions!$B$10*Assumptions!$B$13*J29,0) -> 5.25 | O29: =IF(AND(Assumptions!$B$17,ISNUMBER(J29)),Assumptions!$B$11*Assumptions!$B$13*J29,0) -> 10.5 | P29: =IF(AND(Assumptions!$B$17,ISNUMBER(J29)),Assumptions!$B$12*Assumptions!$B$13*J29,0) -> 15.75 | Q29: =IF(Assumptions!$B$18,Assumptions!$B$14*K29,0) -> 13.9 | R29: =IF(Assumptions!$B$18,Assumptions!$B$15*L29,0) -> 54.36 | S29: =IF(Assumptions!$B$18,Assumptions!$B$16*M29,0) -> 207.9 | T29: =K29+N29+Q29 -> 158.15 | U29: =L29+O29+R29 -> 336.66 | V29: =M29+P29+S29 -> 817.65 | W29: 75 | X29: 180 | Y29: 500 | Z29: =U29-X29 -> 156.66 | AA29: =IFERROR((U29-X29)/X29,"") -> 0.87033333 | AB29: =IF(ISNUMBER(AA29),IF(ABS(AA29)>Assumptions!$B$19,"REVIEW",""),"") -> REVIEW
A30: Basseterre | C30: 80 | D30: 150 | E30: 550 | F30: 25 | G30: 18 | H30: 3 | I30: 1.5 | J30: 5 | K30: =C30+3*Assumptions!$B$4*F30+Assumptions!$B$7*G30+H30+I30 -> 177.5 | L30: =D30+3*Assumptions!$B$5*F30+Assumptions!$B$8*G30+H30+I30 -> 325.5 | M30: =E30+3*Assumptions!$B$6*F30+Assumptions!$B$9*G30+H30+I30 -> 889 | N30: =IF(AND(Assumptions!$B$17,ISNUMBER(J30)),Assumptions!$B$10*Assumptions!$B$13*J30,0) -> 7.5 | O30: =IF(AND(Assumptions!$B$17,ISNUMBER(J30)),Assumptions!$B$11*Assumptions!$B$13*J30,0) -> 15 | P30: =IF(AND(Assumptions!$B$17,ISNUMBER(J30)),Assumptions!$B$12*Assumptions!$B$13*J30,0) -> 22.5 | Q30: =IF(Assumptions!$B$18,Assumptions!$B$14*K30,0) -> 17.75 | R30: =IF(Assumptions!$B$18,Assumptions!$B$15*L30,0) -> 65.1 | S30: =IF(Assumptions!$B$18,Assumptions!$B$16*M30,0) -> 311.15 | T30: =K30+N30+Q30 -> 202.75 | U30: =L30+O30+R30 -> 405.6 | V30: =M30+P30+S30 -> 1222.65 | W30: 85 | X30: 220 | Y30: 650 | Z30: =U30-X30 -> 185.6 | AA30: =IFERROR((U30-X30)/X30,"") -> 0.84363636 | AB30: =IF(ISNUMBER(AA30),IF(ABS(AA30)>Assumptions!$B$19,"REVIEW",""),"") -> REVIEW
A31: Beijing | C31: 35 | D31: 80 | E31: 250 | F31: 12 | G31: 8 | H31: 4.5 | I31: 0.5 | J31: 3 | K31: =C31+3*Assumptions!$B$4*F31+Assumptions!$B$7*G31+H31+I31 -> 84 | L31: =D31+3*Assumptions!$B$5*F31+Assumptions!$B$8*G31+H31+I31 -> 165.8 | M31: =E31+3*Assumptions!$B$6*F31+Assumptions!$B$9*G31+H31+I31 -> 413 | N31: =IF(AND(Assumptions!$B$17,ISNUMBER(J31)),Assumptions!$B$10*Assumptions!$B$13*J31,0) -> 4.5 | O31: =IF(AND(Assumptions!$B$17,ISNUMBER(J31)),Assumptions!$B$11*Assumptions!$B$13*J31,0) -> 9 | P31: =IF(AND(Assumptions!$B$17,ISNUMBER(J31)),Assumptions!$B$12*Assumptions!$B$13*J31,0) -> 13.5 | Q31: =IF(Assumptions!$B$18,Assumptions!$B$14*K31,0) -> 8.4 | R31: =IF(Assumptions!$B$18,Assumptions!$B$15*L31,0) -> 33.16 | S31: =IF(Assumptions!$B$18,Assumptions!$B$16*M31,0) -> 144.55 | T31: =K31+N31+Q31 -> 96.9 | U31: =L31+O31+R31 -> 207.96 | V31: =M31+P31+S31 -> 571.05 | W31: 55 | X31: 135 | Y31: 380 | Z31: =U31-X31 -> 72.96 | AA31: =IFERROR((U31-X31)/X31,"") -> 0.54044444 | AB31: =IF(ISNUMBER(AA31),IF(ABS(AA31)>Assumptions!$B$19,"REVIEW",""),"") -> REVIEW
A32: Beirut | C32: 40 | D32: 90 | E32: 260 | F32: 18 | G32: 8 | H32: 3.5 | I32: 1 | J32: 6 | K32: =C32+3*Assumptions!$B$4*F32+Assumptions!$B$7*G32+H32+I32 -> 106.5 | L32: =D32+3*Assumptions!$B$5*F32+Assumptions!$B$8*G32+H32+I32 -> 207.7 | M32: =E32+3*Assumptions!$B$6*F32+Assumptions!$B$9*G32+H32+I32 -> 485.5 | N32: =IF(AND(Assumptions!$B$17,ISNUMBER(J32)),Assumptions!$B$10*Assumptions!$B$13*J32,0) -> 9 | O32: =IF(AND(Assumptions!$B$17,ISNUMBER(J32)),Assumptions!$B$11*Assumptions!$B$13*J32,0) -> 18 | P32: =IF(AND(Assumptions!$B$17,ISNUMBER(J32)),Assumptions!$B$12*Assumptions!$B$13*J32,0) -> 27 | Q32: =IF(Assumptions!$B$18,Assumptions!$B$14*K32,0) -> 10.65 | R32: =IF(Assumptions!$B$18,Assumptions!$B$15*L32,0) -> 41.54 | S32: =IF(Assumptions!$B$18,Assumptions!$B$16*M32,0) -> 169.925 | T32: =K32+N32+Q32 -> 126.15 | U32: =L32+O32+R32 -> 267.24 | V32: =M32+P32+S32 -> 682.425 | W32: 55 | X32: 135 | Y32: 400 | Z32: =U32-X32 -> 132.24 | AA32: =IFERROR((U32-X32)/X32,"") -> 0.97955556 | AB32: =IF(ISNUMBER(AA32),IF(ABS(AA32)>Assumptions!$B$19,"REVIEW",""),"") -> REVIEW
A33: Belgrade | C33: 25 | D33: 75 | E33: 220 | F33: 15 | G33: 6 | H33: 3 | I33: 1 | J33: 3 | K33: =C33+3*Assumptions!$B$4*F33+Assumptions!$B$7*G33+H33+I33 -> 80 | L33: =D33+3*Assumptions!$B$5*F33+Assumptions!$B$8*G33+H33+I33 -> 172 | M33: =E33+3*Assumptions!$B$6*F33+Assumptions!$B$9*G33+H33+I33 -> 405.5 | N33: =IF(AND(Assumptions!$B$17,ISNUMBER(J33)),Assumptions!$B$10*Assumptions!$B$13*J33,0) -> 4.5 | O33: =IF(AND(Assumptions!$B$17,ISNUMBER(J33)),Assumptions!$B$11*Assumptions!$B$13*J33,0) -> 9 | P33: =IF(AND(Assumptions!$B$17,ISNUMBER(J33)),Assumptions!$B$12*Assumptions!$B$13*J33,0) -> 13.5 | Q33: =IF(Assumptions!$B$18,Assumptions!$B$14*K33,0) -> 8 | R33: =IF(Assumptions!$B$18,Assumptions!$B$15*L33,0) -> 34.4 | S33: =IF(Assumptions!$B$18,Assumptions!$B$16*M33,0) -> 141.925 | T33: =K33+N33+Q33 -> 92.5 | U33: =L33+O33+R33 -> 215.4 | V33: =M33+P33+S33 -> 560.925 | W33: 45 | X33: 110 | Y33: 340 | Z33: =U33-X33 -> 105.4 | AA33: =IFERROR((U33-X33)/X33,"") -> 0.95818182 | AB33: =IF(ISNUMBER(AA33),IF(ABS(AA33)>Assumptions!$B$19,"REVIEW",""),"") -> REVIEW
A34: Belize City | C34: 35 | D34: 90 | E34: 220 | F34: 12 | G34: 7 | H34: 2.5 | I34: 1.5 | J34: 3 | K34: =C34+3*Assumptions!$B$4*F34+Assumptions!$B$7*G34+H34+I34 -> 82 | L34: =D34+3*Assumptions!$B$5*F34+Assumptions!$B$8*G34+H34+I34 -> 172.8 | M34: =E34+3*Assumptions!$B$6*F34+Assumptions!$B$9*G34+H34+I34 -> 378 | N34: =IF(AND(Assumptions!$B$17,ISNUMBER(J34)),Assumptions!$B$10*Assumptions!$B$13*J34,0) -> 4.5 | O34: =IF(AND(Assumptions!$B$17,ISNUMBER(J34)),Assumptions!$B$11*Assumptions!$B$13*J34,0) -> 9 | P34: =IF(AND(Assumptions!$B$17,ISNUMBER(J34)),Assumptions!$B$12*Assumptions!$B$13*J34,0) -> 13.5 | Q34: =IF(Assumptions!$B$18,Assumptions!$B$14*K34,0) -> 8.2 | R34: =IF(Assumptions!$B$18,Assumptions!$B$15*L34,0) -> 34.56 | S34: =IF(Assumptions!$B$18,Assumptions!$B$16*M34,0) -> 132.3 | T34: =K34+N34+Q34 -> 94.7 | U34: =L34+O34+R34 -> 216.36 | V34: =M34+P34+S34 -> 523.8 | W34: 45 | X34: 110 | Y34: 330 | Z34: =U34-X34 -> 106.36 | AA34: =IFERROR((U34-X34)/X34,"") -> 0.96690909 | AB34: =IF(ISNUMBER(AA34),IF(ABS(AA34)>Assumptions!$B$19,"REVIEW",""),"") -> REVIEW
A35: Bengaluru | C35: 20 | D35: 55 | E35: 130 | F35: 6 | G35: 3 | H35: 1.5 | I35: 0.4 | J35: 3 | K35: =C35+3*Assumptions!$B$4*F35+Assumptions!$B$7*G35+H35+I35 -> 42.9 | L35: =D35+3*Assumptions!$B$5*F35+Assumptions!$B$8*G35+H35+I35 -> 95.3 | M35: =E35+3*Assumptions!$B$6*F35+Assumptions!$B$9*G35+H35+I35 -> 206.9 | N35: =IF(AND(Assumptions!$B$17,ISNUMBER(J35)),Assumptions!$B$10*Assumptions!$B$13*J35,0) -> 4.5 | O35: =IF(AND(Assumptions!$B$17,ISNUMBER(J35)),Assumptions!$B$11*Assumptions!$B$13*J35,0) -> 9 | P35: =IF(AND(Assumptions!$B$17,ISNUMBER(J35)),Assumptions!$B$12*Assumptions!$B$13*J35,0) -> 13.5 | Q35: =IF(Assumptions!$B$18,Assumptions!$B$14*K35,0) -> 4.29 | R35: =IF(Assumptions!$B$18,Assumptions!$B$15*L35,0) -> 19.06 | S35: =IF(Assumptions!$B$18,Assumptions!$B$16*M35,0) -> 72.415 | T35: =K35+N35+Q35 -> 51.69 | U35: =L35+O35+R35 -> 123.36 | V35: =M35+P35+S35 -> 292.815 | W35: 30 | X35: 75 | Y35: 220 | Z35: =U35-X35 -> 48.36 | AA35: =IFERROR((U35-X35)/X35,"") -> 0.6448 | AB35: =IF(ISNUMBER(AA35),IF(ABS(AA35)>Assumptions!$B$19,"REVIEW",""),"") -> REVIEW
A36: Berlin | C36: 60 | D36: 110 | E36: 260 | F36: 18 | G36: 25 | H36: 3.2 | I36: 2.5 | J36: 4 | K36: =C36+3*Assumptions!$B$4*F36+Assumptions!$B$7*G36+H36+I36 -> 144.7 | L36: =D36+3*Assumptions!$B$5*F36+Assumptions!$B$8*G36+H36+I36 -> 262.9 | M36: =E36+3*Assumptions!$B$6*F36+Assumptions!$B$9*G36+H36+I36 -> 554.7 | N36: =IF(AND(Assumptions!$B$17,ISNUMBER(J36)),Assumptions!$B$10*Assumptions!$B$13*J36,0) -> 6 | O36: =IF(AND(Assumptions!$B$17,ISNUMBER(J36)),Assumptions!$B$11*Assumptions!$B$13*J36,0) -> 12 | P36: =IF(AND(Assumptions!$B$17,ISNUMBER(J36)),Assumptions!$B$12*Assumptions!$B$13*J36,0) -> 18 | Q36: =IF(Assumptions!$B$18,Assumptions!$B$14*K36,0) -> 14.47 | R36: =IF(Assumptions!$B$18,Assumptions!$B$15*L36,0) -> 52.58 | S36: =IF(Assumptions!$B$18,Assumptions!$B$16*M36,0) -> 194.145 | T36: =K36+N36+Q36 -> 165.17 | U36: =L36+O36+R36 -> 327.48 | V36: =M36+P36+S36 -> 766.845 | W36: 70 | X36: 170 | Y36: 470 | Z36: =U36-X36 -> 157.48 | AA36: =IFERROR((U36-X36)/X36,"") -> 0.92635294 | AB36: =IF(ISNUMBER(AA36),IF(ABS(AA36)>Assumptions!$B$19,"REVIEW",""),"") -> REVIEW
A37: Bishkek | C37: 15 | D37: 45 | E37: 180 | F37: 8 | G37: 3 | H37: 2 | I37: 0.4 | J37: 1.3 | K37: =C37+3*Assumptions!$B$4*F37+Assumptions!$B$7*G37+H37+I37 -> 44.4 | L37: =D37+3*Assumptions!$B$5*F37+Assumptions!$B$8*G37+H37+I37 -> 96.6 | M37: =E37+3*Assumptions!$B$6*F37+Assumptions!$B$9*G37+H37+I37 -> 278.4 | N37: =IF(AND(Assumptions!$B$17,ISNUMBER(J37)),Assumptions!$B$10*Assumptions!$B$13*J37,0) -> 1.95 | O37: =IF(AND(Assumptions!$B$17,ISNUMBER(J37)),Assumptions!$B$11*Assumptions!$B$13*J37,0) -> 3.9 | P37: =IF(AND(Assumptions!$B$17,ISNUMBER(J37)),Assumptions!$B$12*Assumptions!$B$13*J37,0) -> 5.85 | Q37: =IF(Assumptions!$B$18,Assumptions!$B$14*K37,0) -> 4.44 | R37: =IF(Assumptions!$B$18,Assumptions!$B$15*L37,0) -> 19.32 | S37: =IF(Assumptions!$B$18,Assumptions!$B$16*M37,0) -> 97.44 | T37: =K37+N37+Q37 -> 50.79 | U37: =L37+O37+R37 -> 119.82 | V37: =M37+P37+S37 -> 381.69 | W37: 30 | X37: 80 | Y37: 250 | Z37: =U37-X37 -> 39.82 | AA37: =IFERROR((U37-X37)/X37,"") -> 0.49775 | AB37: =IF(ISNUMBER(AA37),IF(ABS(AA37)>Assumptions!$B$19,"REVIEW",""),"") -> REVIEW
... A69: Denpasar | C69: 25 | D69: 60 | E69: 180 | F69: 12 | G69: 12 | H69: 2 | I69: 0.5 | J69: 2.5 | K69: =C69+3*Assumptions!$B$4*F69+Assumptions!$B$7*G69+H69+I69 -> 75.5 | L69: =D69+3*Assumptions!$B$5*F69+Assumptions!$B$8*G69+H69+I69 -> 151.3 | M69: =E69+3*Assumptions!$B$6*F69+Assumptions!$B$9*G69+H69+I69 -> 356.5 | N69: =IF(AND(Assumptions!$B$17,ISNUMBER(J69)),Assumptions!$B$10*Assumptions!$B$13*J69,0) -> 3.75 | O69: =IF(AND(Assumptions!$B$17,ISNUMBER(J69)),Assumptions!$B$11*Assumptions!$B$13*J69,0) -> 7.5 | P69: =IF(AND(Assumptions!$B$17,ISNUMBER(J69)),Assumptions!$B$12*Assumptions!$B$13*J69,0) -> 11.25 | Q69: =IF(Assumptions!$B$18,Assumptions!$B$14*K69,0) -> 7.55 | R69: =IF(Assumptions!$B$18,Assumptions!$B$15*L69,0) -> 30.26 | S69: =IF(Assumptions!$B$18,Assumptions!$B$16*M69,0) -> 124.775 | T69: =K69+N69+Q69 -> 86.8 | U69: =L69+O69+R69 -> 189.06 | V69: =M69+P69+S69 -> 492.525 | W69: 35 | X69: 85 | Y69: 280 | Z69: =U69-X69 -> 104.06 | AA69: =IFERROR((U69-X69)/X69,"") -> 1.2242353 | AB69: =IF(ISNUMBER(AA69),IF(ABS(AA69)>Assumptions!$B$19,"REVIEW",""),"") -> REVIEW
A70: Dhaka | B70: restricted | C70: 20 | D70: 70 | E70: 180 | F70: 6 | G70: 4 | H70: 2.5 | I70: 0.3 | K70: =C70+3*Assumptions!$B$4*F70+Assumptions!$B$7*G70+H70+I70 -> 44.8 | L70: =D70+3*Assumptions!$B$5*F70+Assumptions!$B$8*G70+H70+I70 -> 113.2 | M70: =E70+3*Assumptions!$B$6*F70+Assumptions!$B$9*G70+H70+I70 -> 261.8 | N70: =IF(AND(Assumptions!$B$17,ISNUMBER(J70)),Assumptions!$B$10*Assumptions!$B$13*J70,0) -> 0 | O70: =IF(AND(Assumptions!$B$17,ISNUMBER(J70)),Assumptions!$B$11*Assumptions!$B$13*J70,0) -> 0 | P70: =IF(AND(Assumptions!$B$17,ISNUMBER(J70)),Assumptions!$B$12*Assumptions!$B$13*J70,0) -> 0 | Q70: =IF(Assumptions!$B$18,Assumptions!$B$14*K70,0) -> 4.48 | R70: =IF(Assumptions!$B$18,Assumptions!$B$15*L70,0) -> 22.64 | S70: =IF(Assumptions!$B$18,Assumptions!$B$16*M70,0) -> 91.63 | T70: =K70+N70+Q70 -> 49.28 | U70: =L70+O70+R70 -> 135.84 | V70: =M70+P70+S70 -> 353.43 | W70: 30 | X70: 80 | Y70: 240 | Z70: =U70-X70 -> 55.84 | AA70: =IFERROR((U70-X70)/X70,"") -> 0.698 | AB70: =IF(ISNUMBER(AA70),IF(ABS(AA70)>Assumptions!$B$19,"REVIEW",""),"") -> REVIEW
A71: Dili | C71: 20 | D71: 70 | E71: 150 | F71: 10 | G71: 4 | H71: 2 | I71: 1 | J71: 3.5 | K71: =C71+3*Assumptions!$B$4*F71+Assumptions!$B$7*G71+H71+I71 -> 57 | L71: =D71+3*Assumptions!$B$5*F71+Assumptions!$B$8*G71+H71+I71 -> 135 | M71: =E71+3*Assumptions!$B$6*F71+Assumptions!$B$9*G71+H71+I71 -> 274 | N71: =IF(AND(Assumptions!$B$17,ISNUMBER(J71)),Assumptions!$B$10*Assumptions!$B$13*J71,0) -> 5.25 | O71: =IF(AND(Assumptions!$B$17,ISNUMBER(J71)),Assumptions!$B$11*Assumptions!$B$13*J71,0) -> 10.5 | P71: =IF(AND(Assumptions!$B$17,ISNUMBER(J71)),Assumptions!$B$12*Assumptions!$B$13*J71,0) -> 15.75 | Q71: =IF(Assumptions!$B$18,Assumptions!$B$14*K71,0) -> 5.7 | R71: =IF(Assumptions!$B$18,Assumptions!$B$15*L71,0) -> 27 | S71: =IF(Assumptions!$B$18,Assumptions!$B$16*M71,0) -> 95.9 | T71: =K71+N71+Q71 -> 67.95 | U71: =L71+O71+R71 -> 172.5 | V71: =M71+P71+S71 -> 385.65 | W71: 35 | X71: 85 | Y71: 260 | Z71: =U71-X71 -> 87.5 | AA71: =IFERROR((U71-X71)/X71,"") -> 1.0294118 | AB71: =IF(ISNUMBER(AA71),IF(ABS(AA71)>Assumptions!$B$19,"REVIEW",""),"") -> REVIEW
A72: Djibouti City | C72: 30 | D72: 90 | E72: 260 | F72: 12 | G72: 5 | H72: 2.5 | I72: 1 | J72: 5 | K72: =C72+3*Assumptions!$B$4*F72+Assumptions!$B$7*G72+H72+I72 -> 74.5 | L72: =D72+3*Assumptions!$B$5*F72+Assumptions!$B$8*G72+H72+I72 -> 168.3 | M72: =E72+3*Assumptions!$B$6*F72+Assumptions!$B$9*G72+H72+I72 -> 409.5 | N72: =IF(AND(Assumptions!$B$17,ISNUMBER(J72)),Assumptions!$B$10*Assumptions!$B$13*J72,0) -> 7.5 | O72: =IF(AND(Assumptions!$B$17,ISNUMBER(J72)),Assumptions!$B$11*Assumptions!$B$13*J72,0) -> 15 | P72: =IF(AND(Assumptions!$B$17,ISNUMBER(J72)),Assumptions!$B$12*Assumptions!$B$13*J72,0) -> 22.5 | Q72: =IF(Assumptions!$B$18,Assumptions!$B$14*K72,0) -> 7.45 | R72: =IF(Assumptions!$B$18,Assumptions!$B$15*L72,0) -> 33.66 | S72: =IF(Assumptions!$B$18,Assumptions!$B$16*M72,0) -> 143.325 | T72: =K72+N72+Q72 -> 89.45 | U72: =L72+O72+R72 -> 216.96 | V72: =M72+P72+S72 -> 575.325 | W72: 45 | X72: 110 | Y72: 340 | Z72: =U72-X72 -> 106.96 | AA72: =IFERROR((U72-X72)/X72,"") -> 0.97236364 | AB72: =IF(ISNUMBER(AA72),IF(ABS(AA72)>Assumptions!$B$19,"REVIEW",""),"") -> REVIEW
A73: Doha | B73: restricted | C73: 80 | D73: 150 | E73: 400 | F73: 30 | G73: 15 | H73: 5 | I73: 1 | K73: =C73+3*Assumptions!$B$4*F73+Assumptions!$B$7*G73+H73+I73 -> 191 | L73: =D73+3*Assumptions!$B$5*F73+Assumptions!$B$8*G73+H73+I73 -> 348 | M73: =E73+3*Assumptions!$B$6*F73+Assumptions!$B$9*G73+H73+I73 -> 781 | N73: =IF(AND(Assumptions!$B$17,ISNUMBER(J73)),Assumptions!$B$10*Assumptions!$B$13*J73,0) -> 0 | O73: =IF(AND(Assumptions!$B$17,ISNUMBER(J73)),Assumptions!$B$11*Assumptions!$B$13*J73,0) -> 0 | P73: =IF(AND(Assumptions!$B$17,ISNUMBER(J73)),Assumptions!$B$12*Assumptions!$B$13*J73,0) -> 0 | Q73: =IF(Assumptions!$B$18,Assumptions!$B$14*K73,0) -> 19.1 | R73: =IF(Assumptions!$B$18,Assumptions!$B$15*L73,0) -> 69.6 | S73: =IF(Assumptions!$B$18,Assumptions!$B$16*M73,0) -> 273.35 | T73: =K73+N73+Q73 -> 210.1 | U73: =L73+O73+R73 -> 417.6 | V73: =M73+P73+S73 -> 1054.35 | W73: 70 | X73: 180 | Y73: 550 | Z73: =U73-X73 -> 237.6 | AA73: =IFERROR((U73-X73)/X73,"") -> 1.32 | AB73: =IF(ISNUMBER(AA73),IF(ABS(AA73)>Assumptions!$B$19,"REVIEW",""),"") -> REVIEW
A74: Dongguan | C74: 20 | D74: 55 | E74: 130 | F74: 6 | G74: 4 | H74: 3.5 | I74: 0.4 | J74: 1.5 | K74: =C74+3*Assumptions!$B$4*F74+Assumptions!$B$7*G74+H74+I74 -> 45.9 | L74: =D74+3*Assumptions!$B$5*F74+Assumptions!$B$8*G74+H74+I74 -> 99.3 | M74: =E74+3*Assumptions!$B$6*F74+Assumptions!$B$9*G74+H74+I74 -> 212.9 | N74: =IF(AND(Assumptions!$B$17,ISNUMBER(J74)),Assumptions!$B$10*Assumptions!$B$13*J74,0) -> 2.25 | O74: =IF(AND(Assumptions!$B$17,ISNUMBER(J74)),Assumptions!$B$11*Assumptions!$B$13*J74,0) -> 4.5 | P74: =IF(AND(Assumptions!$B$17,ISNUMBER(J74)),Assumptions!$B$12*Assumptions!$B$13*J74,0) -> 6.75 | Q74: =IF(Assumptions!$B$18,Assumptions!$B$14*K74,0) -> 4.59 | R74: =IF(Assumptions!$B$18,Assumptions!$B$15*L74,0) -> 19.86 | S74: =IF(Assumptions!$B$18,Assumptions!$B$16*M74,0) -> 74.515 | T74: =K74+N74+Q74 -> 52.74 | U74: =L74+O74+R74 -> 123.66 | V74: =M74+P74+S74 -> 294.165 | W74: 30 | X74: 75 | Y74: 200 | Z74: =U74-X74 -> 48.66 | AA74: =IFERROR((U74-X74)/X74,"") -> 0.6488 | AB74: =IF(ISNUMBER(AA74),IF(ABS(AA74)>Assumptions!$B$19,"REVIEW",""),"") -> REVIEW
A75: Douala | C75: 30 | D75: 75 | E75: 250 | F75: 10 | G75: 5 | H75: 2.5 | I75: 0.6 | J75: 2 | K75: =C75+3*Assumptions!$B$4*F75+Assumptions!$B$7*G75+H75+I75 -> 68.1 | L75: =D75+3*Assumptions!$B$5*F75+Assumptions!$B$8*G75+H75+I75 -> 142.1 | M75: =E75+3*Assumptions!$B$6*F75+Assumptions!$B$9*G75+H75+I75 -> 378.1 | N75: =IF(AND(Assumptions!$B$17,ISNUMBER(J75)),Assumptions!$B$10*Assumptions!$B$13*J75,0) -> 3 | O75: =IF(AND(Assumptions!$B$17,ISNUMBER(J75)),Assumptions!$B$11*Assumptions!$B$13*J75,0) -> 6 | P75: =IF(AND(Assumptions!$B$17,ISNUMBER(J75)),Assumptions!$B$12*Assumptions!$B$13*J75,0) -> 9 | Q75: =IF(Assumptions!$B$18,Assumptions!$B$14*K75,0) -> 6.81 | R75: =IF(Assumptions!$B$18,Assumptions!$B$15*L75,0) -> 28.42 | S75: =IF(Assumptions!$B$18,Assumptions!$B$16*M75,0) -> 132.335 | T75: =K75+N75+Q75 -> 77.91 | U75: =L75+O75+R75 -> 176.52 | V75: =M75+P75+S75 -> 519.435 | W75: 40 | X75: 105 | Y75: 320 | Z75: =U75-X75 -> 71.52 | AA75: =IFERROR((U75-X75)/X75,"") -> 0.68114286 | AB75: =IF(ISNUMBER(AA75),IF(ABS(AA75)>Assumptions!$B$19,"REVIEW",""),"") -> REVIEW
A76: Dubai | B76: restricted | C76: 50 | D76: 120 | E76: 350 | F76: 25 | G76: 8 | H76: 4.5 | I76: 0.5 | K76: =C76+3*Assumptions!$B$4*F76+Assumptions!$B$7*G76+H76+I76 -> 138 | L76: =D76+3*Assumptions!$B$5*F76+Assumptions!$B$8*G76+H76+I76 -> 276 | M76: =E76+3*Assumptions!$B$6*F76+Assumptions!$B$9*G76+H76+I76 -> 649.5 | N76: =IF(AND(Assumptions!$B$17,ISNUMBER(J76)),Assumptions!$B$10*Assumptions!$B$13*J76,0) -> 0 | O76: =IF(AND(Assumptions!$B$17,ISNUMBER(J76)),Assumptions!$B$11*Assumptions!$B$13*J76,0) -> 0 | P76: =IF(AND(Assumptions!$B$17,ISNUMBER(J76)),Assumptions!$B$12*Assumptions!$B$13*J76,0) -> 0 | Q76: =IF(Assumptions!$B$18,Assumptions!$B$14*K76,0) -> 13.8 | R76: =IF(Assumptions!$B$18,Assumptions!$B$15*L76,0) -> 55.2 | S76: =IF(Assumptions!$B$18,Assumptions!$B$16*M76,0) -> 227.325 | T76: =K76+N76+Q76 -> 151.8 | U76: =L76+O76+R76 -> 331.2 | V76: =M76+P76+S76 -> 876.825 | W76: 75 | X76: 200 | Y76: 650 | Z76: =U76-X76 -> 131.2 | AA76: =IFERROR((U76-X76)/X76,"") -> 0.656 | AB76: =IF(ISNUMBER(AA76),IF(ABS(AA76)>Assumptions!$B$19,"REVIEW",""),"") -> REVIEW
A77: Dublin | C77: 90 | D77: 160 | E77: 350 | F77: 25 | G77: 30 | H77: 3.5 | I77: 2 | J77: 6.5 | K77: =C77+3*Assumptions!$B$4*F77+Assumptions!$B$7*G77+H77+I77 -> 200.5 | L77: =D77+3*Assumptions!$B$5*F77+Assumptions!$B$8*G77+H77+I77 -> 360.5 | M77: =E77+3*Assumptions!$B$6*F77+Assumptions!$B$9*G77+H77+I77 -> 738 | N77: =IF(AND(Assumptions!$B$17,ISNUMBER(J77)),Assumptions!$B$10*Assumptions!$B$13*J77,0) -> 9.75 | O77: =IF(AND(Assumptions!$B$17,ISNUMBER(J77)),Assumptions!$B$11*Assumptions!$B$13*J77,0) -> 19.5 | P77: =IF(AND(Assumptions!$B$17,ISNUMBER(J77)),Assumptions!$B$12*Assumptions!$B$13*J77,0) -> 29.25 | Q77: =IF(Assumptions!$B$18,Assumptions!$B$14*K77,0) -> 20.05 | R77: =IF(Assumptions!$B$18,Assumptions!$B$15*L77,0) -> 72.1 | S77: =IF(Assumptions!$B$18,Assumptions!$B$16*M77,0) -> 258.3 | T77: =K77+N77+Q77 -> 230.3 | U77: =L77+O77+R77 -> 452.1 | V77: =M77+P77+S77 -> 1025.55 | W77: 85 | X77: 210 | Y77: 580 | Z77: =U77-X77 -> 242.1 | AA77: =IFERROR((U77-X77)/X77,"") -> 1.1528571 | AB77: =IF(ISNUMBER(AA77),IF(ABS(AA77)>Assumptions!$B$19,"REVIEW",""),"") -> REVIEW
A78: Dubrovnik | C78: 50 | D78: 160 | E78: 420 | F78: 25 | G78: 15 | H78: 3 | I78: 2 | J78: 4.5 | K78: =C78+3*Assumptions!$B$4*F78+Assumptions!$B$7*G78+H78+I78 -> 145 | L78: =D78+3*Assumptions!$B$5*F78+Assumptions!$B$8*G78+H78+I78 -> 330 | M78: =E78+3*Assumptions!$B$6*F78+Assumptions!$B$9*G78+H78+I78 -> 747.5 | N78: =IF(AND(Assumptions!$B$17,ISNUMBER(J78)),Assumptions!$B$10*Assumptions!$B$13*J78,0) -> 6.75 | O78: =IF(AND(Assumptions!$B$17,ISNUMBER(J78)),Assumptions!$B$11*Assumptions!$B$13*J78,0) -> 13.5 | P78: =IF(AND(Assumptions!$B$17,ISNUMBER(J78)),Assumptions!$B$12*Assumptions!$B$13*J78,0) -> 20.25 | Q78: =IF(Assumptions!$B$18,Assumptions!$B$14*K78,0) -> 14.5 | R78: =IF(Assumptions!$B$18,Assumptions!$B$15*L78,0) -> 66 | S78: =IF(Assumptions!$B$18,Assumptions!$B$16*M78,0) -> 261.625 | T78: =K78+N78+Q78 -> 166.25 | U78: =L78+O78+R78 -> 409.5 | V78: =M78+P78+S78 -> 1029.375 | W78: 70 | X78: 180 | Y78: 545 | Z78: =U78-X78 -> 229.5 | AA78: =IFERROR((U78-X78)/X78,"") -> 1.275 | AB78: =IF(ISNUMBER(AA78),IF(ABS(AA78)>Assumptions!$B$19,"REVIEW",""),"") -> REVIEW
A79: Dushanbe | C79: 15 | D79: 55 | E79: 180 | F79: 10 | G79: 3 | H79: 2 | I79: 0.5 | J79: 1.5 | K79: =C79+3*Assumptions!$B$4*F79+Assumptions!$B$7*G79+H79+I79 -> 50.5 | L79: =D79+3*Assumptions!$B$5*F79+Assumptions!$B$8*G79+H79+I79 -> 117.5 | M79: =E79+3*Assumptions!$B$6*F79+Assumptions!$B$9*G79+H79+I79 -> 299.5 | N79: =IF(AND(Assumptions!$B$17,ISNUMBER(J79)),Assumptions!$B$10*Assumptions!$B$13*J79,0) -> 2.25 | O79: =IF(AND(Assumptions!$B$17,ISNUMBER(J79)),Assumptions!$B$11*Assumptions!$B$13*J79,0) -> 4.5 | P79: =IF(AND(Assumptions!$B$17,ISNUMBER(J79)),Assumptions!$B$12*Assumptions!$B$13*J79,0) -> 6.75 | Q79: =IF(Assumptions!$B$18,Assumptions!$B$14*K79,0) -> 5.05 | R79: =IF(Assumptions!$B$18,Assumptions!$B$15*L79,0) -> 23.5 | S79: =IF(Assumptions!$B$18,Assumptions!$B$16*M79,0) -> 104.825 | T79: =K79+N79+Q79 -> 57.8 | U79: =L79+O79+R79 -> 145.5 | V79: =M79+P79+S79 -> 411.075 | W79: 35 | X79: 85 | Y79: 265 | Z79: =U79-X79 -> 60.5 | AA79: =IFERROR((U79-X79)/X79,"") -> 0.71176471 | AB79: =IF(ISNUMBER(AA79),IF(ABS(AA79)>Assumptions!$B$19,"REVIEW",""),"") -> REVIEW
...
