Workbook

Sheet About
A1: Never Roam Alone — Master City List
A3: Generated | B3: July 7, 2026
A4: Visitor Score weights (change these to re-blend the score):
A5: Aviation hub weight | B5: 0.4 | C5: Flight-traffic rank of the busiest airport serving the city. Source: OpenTravelData ref_airport_pageranked.csv (flight schedules), July 2026, log-scaled so 1.0 = world #1 (Istanbul).
A6: Tourism index weight | B6: 0.4 | C6: 1.0 if the city appears on Euromonitor Top 100 City Destinations (via the site's 101 featured cities) or Mastercard Global Destination Cities Index Top 20 (2019, final edition).
A7: POI density weight | B7: 0.2 | C7: Hotel/hostel/attraction density from OpenStreetMap. Not filled yet — run poi-density.mjs on your Mac to fill it. Until then the score auto-renormalizes to 50/50 aviation/index.
A9: Inclusion criteria (any one): population ≥100,000 · national capital · population ≥20,000 with own commercial airport (IATA, scheduled service, city match or ≤10 km) · on a tourism index.
A10: City data: GeoNames (via all-the-cities). Airports: OurAirports, July 2026. Population figures are the latest in GeoNames and may lag official censuses.

Sheet Master List
A1: City | B1: Country | C1: Country Population | D1: ISO | E1: Admin | F1: Population | G1: Capital | H1: Main airport (IATA) | I1: Airport name | J1: Airport dist (km) | K1: All nearby airports | L1: Qualifies by | M1: Aviation score | N1: Index score | O1: POI score (pending) | P1: Visitor Score | Q1: Latitude | R1: Longitude
A2: Istanbul | B2: Türkiye | C2: 86092168 | D2: TR | E2: 34 | F2: 14804116 | H2: IST | I2: İstanbul Airport | J2: 34.3 | K2: IST | L2: 100k + pop + airport | M2: 1 | N2: 1 | P2: =IF(O2="",(About!$B$5*M2+About!$B$6*N2)/(About!$B$5+About!$B$6),About!$B$5*M2+About!$B$6*N2+About!$B$7*O2) | Q2: 41.0138 | R2: 28.9497
A3: Frankfurt am Main | B3: Germany | C3: 83497147 | D3: DE | E3: 05 | F3: 650000 | H3: FRA | I3: Frankfurt Main Airport | J3: 13.3 | K3: FRA | L3: 100k + pop + airport | M3: 0.963 | N3: 1 | P3: =IF(O3="",(About!$B$5*M3+About!$B$6*N3)/(About!$B$5+About!$B$6),About!$B$5*M3+About!$B$6*N3+About!$B$7*O3) | Q3: 50.1155 | R3: 8.6842
A4: London | B4: United Kingdom | C4: 69487000 | D4: GB | E4: ENG | F4: 7556900 | G4: Yes | H4: LHR | I4: London Heathrow Airport | J4: 23.5 | K4: LCY+LGW+LHR | L4: 100k + pop + capital + airport | M4: 0.954 | N4: 1 | P4: =IF(O4="",(About!$B$5*M4+About!$B$6*N4)/(About!$B$5+About!$B$6),About!$B$5*M4+About!$B$6*N4+About!$B$7*O4) | Q4: 51.5085 | R4: -0.1257
A5: New York City | B5: United States | C5: 341784857 | D5: US | E5: NY | F5: 8922483 | H5: JFK | I5: John F. Kennedy International Airport | J5: 20.8 | K5: EWR+JFK+JRA+LGA+NYS+TEB+TSS | L5: 100k + pop + airport | M5: 0.943 | N5: 1 | P5: =IF(O5="",(About!$B$5*M5+About!$B$6*N5)/(About!$B$5+About!$B$6),About!$B$5*M5+About!$B$6*N5+About!$B$7*O5) | Q5: 40.7143 | R5: -74.006
A6: Paris | B6: France | C6: 69081996 | D6: FR | E6: 11 | F6: 4666813 | G6: Yes | H6: CDG | I6: Charles de Gaulle International Airport | J6: 22.9 | K6: CDG+LBG+ORY | L6: 100k + pop + capital + airport | M6: 0.938 | N6: 1 | P6: =IF(O6="",(About!$B$5*M6+About!$B$6*N6)/(About!$B$5+About!$B$6),About!$B$5*M6+About!$B$6*N6+About!$B$7*O6) | Q6: 48.8534 | R6: 2.3488
A7: Marne-la-Vallée | B7: France | C7: 69081996 | D7: FR | E7: 11 | F7: 320000 | K7: CDG | L7: index | M7: 0.938 | N7: 1 | P7: =IF(O7="",(About!$B$5*M7+About!$B$6*N7)/(About!$B$5+About!$B$6),About!$B$5*M7+About!$B$6*N7+About!$B$7*O7) | Q7: 48.8547 | R7: 2.7744
A8: Los Angeles | B8: United States | C8: 341784857 | D8: US | E8: CA | F8: 3971883 | H8: LAX | I8: Los Angeles International Airport | J8: 19.5 | K8: BUR+HHR+LAX | L8: 100k + pop + airport | M8: 0.932 | N8: 1 | P8: =IF(O8="",(About!$B$5*M8+About!$B$6*N8)/(About!$B$5+About!$B$6),About!$B$5*M8+About!$B$6*N8+About!$B$7*O8) | Q8: 34.0522 | R8: -118.2437
A9: Amsterdam | B9: Netherlands | C9: 18147273 | D9: NL | E9: 07 | F9: 741636 | G9: Yes | H9: AMS | I9: Amsterdam Airport Schiphol | J9: 11.2 | K9: AMS | L9: 100k + pop + capital + airport | M9: 0.931 | N9: 1 | P9: =IF(O9="",(About!$B$5*M9+About!$B$6*N9)/(About!$B$5+About!$B$6),About!$B$5*M9+About!$B$6*N9+About!$B$7*O9) | Q9: 52.374 | R9: 4.8897
A10: San Francisco | B10: United States | C10: 341784857 | D10: US | E10: CA | F10: 864816 | H10: SFO | I10: San Francisco International Airport | J10: 17.7 | K10: OAK+SFO | L10: 100k + pop + airport | M10: 0.92 | N10: 1 | P10: =IF(O10="",(About!$B$5*M10+About!$B$6*N10)/(About!$B$5+About!$B$6),About!$B$5*M10+About!$B$6*N10+About!$B$7*O10) | Q10: 37.7749 | R10: -122.4194
A11: Tokyo | B11: Japan | C11: 122810000 | D11: JP | E11: 40 | F11: 15674774 | G11: Yes | H11: HND | I11: Tokyo Haneda International Airport | J11: 17.8 | K11: HND | L11: 100k + pop + capital + airport | M11: 0.908 | N11: 1 | P11: =IF(O11="",(About!$B$5*M11+About!$B$6*N11)/(About!$B$5+About!$B$6),About!$B$5*M11+About!$B$6*N11+About!$B$7*O11) | Q11: 35.6895 | R11: 139.6917
A12: Sydney | B12: Australia | C12: 27724744 | D12: AU | E12: 02 | F12: 4627345 | H12: SYD | I12: Sydney Kingsford Smith International Airport | J12: 9.1 | K12: LBH+SYD+WSI | L12: 100k + pop + airport | M12: 0.909 | N12: 1 | P12: =IF(O12="",(About!$B$5*M12+About!$B$6*N12)/(About!$B$5+About!$B$6),About!$B$5*M12+About!$B$6*N12+About!$B$7*O12) | Q12: -33.8678 | R12: 151.2073
A13: Las Vegas | B13: United States | C13: 341784857 | D13: US | E13: NV | F13: 846914 | H13: LAS | I13: Harry Reid International Airport | J13: 10.3 | K13: LAS | L13: 100k + pop + airport | M13: 0.905 | N13: 1 | P13: =IF(O13="",(About!$B$5*M13+About!$B$6*N13)/(About!$B$5+About!$B$6),About!$B$5*M13+About!$B$6*N13+About!$B$7*O13) | Q13: 36.175 | R13: -115.1372
A14: Dubai | B14: UAE | C14: 11294243 | D14: AE | E14: 03 | F14: 2956587 | H14: DXB | I14: Dubai International Airport | J14: 20.2 | K14: DWC+DXB | L14: 100k + pop + airport | M14: 0.904 | N14: 1 | P14: =IF(O14="",(About!$B$5*M14+About!$B$6*N14)/(About!$B$5+About!$B$6),About!$B$5*M14+About!$B$6*N14+About!$B$7*O14) | Q14: 25.0772 | R14: 55.3093
A15: Sharjah | B15: UAE | C15: 11294243 | D15: AE | E15: 06 | F15: 1324473 | H15: DXB | I15: Dubai International Airport | J15: 10.6 | K15: DXB+SHJ | L15: 100k + pop + airport | M15: 0.904 | N15: 1 | P15: =IF(O15="",(About!$B$5*M15+About!$B$6*N15)/(About!$B$5+About!$B$6),About!$B$5*M15+About!$B$6*N15+About!$B$7*O15) | Q15: 25.3374 | R15: 55.4121
A16: Vienna | B16: Austria | C16: 9220882 | D16: AT | E16: 09 | F16: 1691468 | G16: Yes | H16: VIE | I16: Vienna International Airport | J16: 18.3 | K16: VIE | L16: 100k + pop + capital + airport | M16: 0.899 | N16: 1 | P16: =IF(O16="",(About!$B$5*M16+About!$B$6*N16)/(About!$B$5+About!$B$6),About!$B$5*M16+About!$B$6*N16+About!$B$7*O16) | Q16: 48.2085 | R16: 16.3721
A17: São Paulo | B17: Brazil | C17: 213421037 | D17: BR | E17: 27 | F17: 15627353 | H17: GRU | I17: São Paulo/Guarulhos–Governor André Franco Montoro International Airport | J17: 21.3 | K17: CGH+GRU | L17: 100k + pop + airport | M17: 0.899 | N17: 1 | P17: =IF(O17="",(About!$B$5*M17+About!$B$6*N17)/(About!$B$5+About!$B$6),About!$B$5*M17+About!$B$6*N17+About!$B$7*O17) | Q17: -23.5475 | R17: -46.6361
A18: Doha | B18: Qatar | C18: 3214609 | D18: QA | E18: 01 | F18: 344939 | G18: Yes | H18: DOH | I18: Hamad International Airport | J18: 7.9 | K18: DIA+DOH | L18: 100k + pop + capital + airport | M18: 0.895 | N18: 1 | P18: =IF(O18="",(About!$B$5*M18+About!$B$6*N18)/(About!$B$5+About!$B$6),About!$B$5*M18+About!$B$6*N18+About!$B$7*O18) | Q18: 25.2855 | R18: 51.531
A19: Toronto | B19: Canada | C19: 41472081 | D19: CA | E19: 08 | F19: 2600000 | H19: YYZ | I19: Toronto Pearson International Airport | J19: 17.3 | K19: YTZ+YYZ | L19: 100k + pop + airport | M19: 0.889 | N19: 1 | P19: =IF(O19="",(About!$B$5*M19+About!$B$6*N19)/(About!$B$5+About!$B$6),About!$B$5*M19+About!$B$6*N19+About!$B$7*O19) | Q19: 43.7001 | R19: -79.4163
A20: Barcelona | B20: Spain | C20: 49687120 | D20: ES | E20: 56 | F20: 3161012 | H20: BCN | I20: Josep Tarradellas Barcelona-El Prat Airport | J20: 12.2 | K20: BCN | L20: 100k + pop + airport | M20: 0.889 | N20: 1 | P20: =IF(O20="",(About!$B$5*M20+About!$B$6*N20)/(About!$B$5+About!$B$6),About!$B$5*M20+About!$B$6*N20+About!$B$7*O20) | Q20: 41.3888 | R20: 2.159
A21: Munich | B21: Germany | C21: 83497147 | D21: DE | E21: 02 | F21: 1260391 | H21: MUC | I21: Munich Airport | J21: 28.7 | K21: MUC | L21: 100k + pop + airport | M21: 0.886 | N21: 1 | P21: =IF(O21="",(About!$B$5*M21+About!$B$6*N21)/(About!$B$5+About!$B$6),About!$B$5*M21+About!$B$6*N21+About!$B$7*O21) | Q21: 48.1374 | R21: 11.5755
A22: Bangkok | B22: Thailand | C22: 65826149 | D22: TH | E22: 40 | F22: 5104476 | G22: Yes | H22: BKK | I22: Suvarnabhumi Airport | J22: 27.7 | K22: BKK+DMK | L22: 100k + pop + capital + airport | M22: 0.879 | N22: 1 | P22: =IF(O22="",(About!$B$5*M22+About!$B$6*N22)/(About!$B$5+About!$B$6),About!$B$5*M22+About!$B$6*N22+About!$B$7*O22) | Q22: 13.754 | R22: 100.5014
A23: Brussels | B23: Belgium | C23: 11933850 | D23: BE | E23: BRU | F23: 1019022 | G23: Yes | H23: BRU | I23: Brussels Airport | J23: 11.1 | K23: BRU | L23: 100k + pop + capital | M23: 0.879 | N23: 1 | P23: =IF(O23="",(About!$B$5*M23+About!$B$6*N23)/(About!$B$5+About!$B$6),About!$B$5*M23+About!$B$6*N23+About!$B$7*O23) | Q23: 50.8505 | R23: 4.3488
A24: Madrid | B24: Spain | C24: 49687120 | D24: ES | E24: 29 | F24: 4729915 | G24: Yes | H24: MAD | I24: Adolfo Suárez Madrid–Barajas Airport | J24: 14 | K24: MAD | L24: 100k + pop + capital + airport | M24: 0.874 | N24: 1 | P24: =IF(O24="",(About!$B$5*M24+About!$B$6*N24)/(About!$B$5+About!$B$6),About!$B$5*M24+About!$B$6*N24+About!$B$7*O24) | Q24: 40.4165 | R24: -3.7026
A25: Vancouver | B25: Canada | C25: 41472081 | D25: CA | E25: 02 | F25: 600000 | H25: YVR | I25: Vancouver International Airport | J25: 7.8 | K25: CXH+YVR | L25: 100k + pop + airport | M25: 0.873 | N25: 1 | P25: =IF(O25="",(About!$B$5*M25+About!$B$6*N25)/(About!$B$5+About!$B$6),About!$B$5*M25+About!$B$6*N25+About!$B$7*O25) | Q25: 49.2497 | R25: -123.1193
A26: Shanghai | B26: China | C26: 1404890000 | D26: CN | E26: 23 | F26: 22315474 | H26: SHA | I26: Shanghai Hongqiao International Airport | J26: 12.1 | K26: SHA | L26: 100k + pop | M26: 0.871 | N26: 1 | P26: =IF(O26="",(About!$B$5*M26+About!$B$6*N26)/(About!$B$5+About!$B$6),About!$B$5*M26+About!$B$6*N26+About!$B$7*O26) | Q26: 31.2222 | R26: 121.4581
A27: Delhi | B27: India | C27: 1417492000 | D27: IN | E27: 07 | F27: 13935222 | H27: DEL | I27: Indira Gandhi International Airport | J27: 17.1 | K27: DEL+HDO | L27: 100k + pop | M27: 0.872 | N27: 1 | P27: =IF(O27="",(About!$B$5*M27+About!$B$6*N27)/(About!$B$5+About!$B$6),About!$B$5*M27+About!$B$6*N27+About!$B$7*O27) | Q27: 28.6519 | R27: 77.2315
A28: Miami | B28: United States | C28: 341784857 | D28: US | E28: FL | F28: 441003 | H28: MIA | I28: Miami International Airport | J28: 9.9 | K28: MIA+OPF | L28: 100k + pop + airport | M28: 0.872 | N28: 1 | P28: =IF(O28="",(About!$B$5*M28+About!$B$6*N28)/(About!$B$5+About!$B$6),About!$B$5*M28+About!$B$6*N28+About!$B$7*O28) | Q28: 25.7743 | R28: -80.1937
A29: Zürich | B29: Switzerland | C29: 9124288 | D29: CH | E29: ZH | F29: 341730 | H29: ZRH | I29: Zürich Airport | J29: 10.2 | K29: ZRH | L29: 100k + pop + airport | M29: 0.873 | N29: 1 | P29: =IF(O29="",(About!$B$5*M29+About!$B$6*N29)/(About!$B$5+About!$B$6),About!$B$5*M29+About!$B$6*N29+About!$B$7*O29) | Q29: 47.3667 | R29: 8.55
A30: Buenos Aires | B30: Argentina | C30: 46387098 | D30: AR | E30: 07 | F30: 13076300 | G30: Yes | H30: AEP | I30: Aeroparque Jorge Newbery | J30: 6.9 | K30: AEP | L30: 100k + pop + capital + airport | M30: 0.87 | N30: 1 | P30: =IF(O30="",(About!$B$5*M30+About!$B$6*N30)/(About!$B$5+About!$B$6),About!$B$5*M30+About!$B$6*N30+About!$B$7*O30) | Q30: -34.6131 | R30: -58.3772
A31: Orlando | B31: United States | C31: 341784857 | D31: US | E31: FL | F31: 270934 | H31: MCO | I31: Orlando International Airport | J31: 13.9 | K31: MCO+SFB | L31: 100k + pop + airport | M31: 0.867 | N31: 1 | P31: =IF(O31="",(About!$B$5*M31+About!$B$6*N31)/(About!$B$5+About!$B$6),About!$B$5*M31+About!$B$6*N31+About!$B$7*O31) | Q31: 28.5383 | R31: -81.3792
A32: Mexico City | B32: Mexico | C32: 131150866 | D32: MX | E32: 09 | F32: 20711221 | G32: Yes | H32: MEX | I32: Mexico City Benito Juárez International Airport | J32: 6.1 | K32: MEX+NLU | L32: 100k + pop + capital + airport | M32: 0.865 | N32: 1 | P32: =IF(O32="",(About!$B$5*M32+About!$B$6*N32)/(About!$B$5+About!$B$6),About!$B$5*M32+About!$B$6*N32+About!$B$7*O32) | Q32: 19.4285 | R32: -99.1277
A33: Melbourne | B33: Australia | C33: 27724744 | D33: AU | E33: 07 | F33: 4246375 | H33: MEL | I33: Melbourne Airport | J33: 19.4 | K33: MBW+MEB+MEL | L33: 100k + pop + airport | M33: 0.861 | N33: 1 | P33: =IF(O33="",(About!$B$5*M33+About!$B$6*N33)/(About!$B$5+About!$B$6),About!$B$5*M33+About!$B$6*N33+About!$B$7*O33) | Q33: -37.814 | R33: 144.9633
A34: Beijing | B34: China | C34: 1404890000 | D34: CN | E34: 22 | F34: 11716620 | G34: Yes | H34: PEK | I34: Beijing Capital International Airport | J34: 25.4 | K34: PEK+PKX | L34: 100k + pop + capital + airport | M34: 0.854 | N34: 1 | P34: =IF(O34="",(About!$B$5*M34+About!$B$6*N34)/(About!$B$5+About!$B$6),About!$B$5*M34+About!$B$6*N34+About!$B$7*O34) | Q34: 39.9075 | R34: 116.3972
A35: Washington, D.C. | B35: United States | C35: 341784857 | D35: US | E35: DC | F35: 601723 | G35: Yes | H35: DCA | I35: Ronald Reagan Washington National Airport | J35: 4.8 | K35: DCA | L35: 100k + pop + capital + airport | M35: 0.851 | N35: 1 | P35: =IF(O35="",(About!$B$5*M35+About!$B$6*N35)/(About!$B$5+About!$B$6),About!$B$5*M35+About!$B$6*N35+About!$B$7*O35) | Q35: 38.8951 | R35: -77.0364
A36: Singapore | B36: Singapore | C36: 6110200 | D36: SG | E36: 01 | F36: 3547809 | G36: Yes | H36: SIN | I36: Singapore Changi Airport | J36: 17.4 | K36: SIN+XSP | L36: 100k + pop + capital + airport | M36: 0.847 | N36: 1 | P36: =IF(O36="",(About!$B$5*M36+About!$B$6*N36)/(About!$B$5+About!$B$6),About!$B$5*M36+About!$B$6*N36+About!$B$7*O36) | Q36: 1.2897 | R36: 103.8501
A37: Montréal | B37: Canada | C37: 41472081 | D37: CA | E37: 10 | F37: 1600000 | H37: YUL | I37: Montreal / Pierre Elliott Trudeau International Airport | J37: 12.9 | K37: YHU+YMX+YUL | L37: 100k + pop + airport | M37: 0.849 | N37: 1 | P37: =IF(O37="",(About!$B$5*M37+About!$B$6*N37)/(About!$B$5+About!$B$6),About!$B$5*M37+About!$B$6*N37+About!$B$7*O37) | Q37: 45.5088 | R37: -73.5878
A38: Shenzhen | B38: China | C38: 1404890000 | D38: CN | E38: 30 | F38: 10358381 | H38: SZX | I38: Shenzhen Bao'an International Airport | J38: 29.1 | K38: SZX | L38: 100k + pop + airport | M38: 0.846 | N38: 1 | P38: =IF(O38="",(About!$B$5*M38+About!$B$6*N38)/(About!$B$5+About!$B$6),About!$B$5*M38+About!$B$6*N38+About!$B$7*O38) | Q38: 22.5455 | R38: 114.0683
A39: Rome | B39: Italy | C39: 58932330 | D39: IT | E39: 07 | F39: 2562213 | G39: Yes | H39: FCO | I39: Rome–Fiumicino Leonardo da Vinci International Airport | J39: 23.6 | K39: CIA+FCO | L39: 100k + pop + capital + airport | M39: 0.838 | N39: 1 | P39: =IF(O39="",(About!$B$5*M39+About!$B$6*N39)/(About!$B$5+About!$B$6),About!$B$5*M39+About!$B$6*N39+About!$B$7*O39) | Q39: 41.8919 | R39: 12.5113
A40: Santiago | B40: Chile | C40: 20206953 | D40: CL | E40: 12 | F40: 4837295 | G40: Yes | H40: SCL | I40: Comodoro Arturo Merino Benítez International Airport | J40: 14.6 | K40: SCL | L40: 100k + pop + capital + airport | M40: 0.836 | N40: 1 | P40: =IF(O40="",(About!$B$5*M40+About!$B$6*N40)/(About!$B$5+About!$B$6),About!$B$5*M40+About!$B$6*N40+About!$B$7*O40) | Q40: -33.4569 | R40: -70.6483
...

Sheet Second Tier Cities
A1: City | B1: Country | C1: Country Population | D1: ISO | E1: Admin | F1: Population | G1: Capital | H1: Main airport (IATA) | I1: Airport name | J1: Airport dist (km) | K1: All nearby airports | L1: Qualifies by | M1: Aviation score | N1: Index score | O1: POI score (pending) | P1: Visitor Score | Q1: Latitude | R1: Longitude
